Workbook

Sheet 交易记录
A1: 成交日期 | B1: 成交净值 | C1: 确认份额 | D1: 交易类型 | E1: 金额 | F1: 手续费（元）
A2: 46317 | B2: =IF($A2="","",IFERROR(VLOOKUP($A2,全部历史净值!$A:$B,2,FALSE),"")) | C2: =IF(OR($A2="",$B2="",$D2="",$E2=""),"",IF(OR($D2="买入",$D2="定投",$D2="转入",$D2="转换转入"),ROUND(($E2-$F2)/$B2,6),IF($D2="卖出",ROUND(($E2+$F2)/$B2,6),""))) | D2: 买入 | E2: 3000 | F2: =IF($E2="","",IF($D2="卖出","",0)) -> 0
B3: =IF($A3="","",IFERROR(VLOOKUP($A3,全部历史净值!$A:$B,2,FALSE),"")) | C3: =IF(OR($A3="",$B3="",$D3="",$E3=""),"",IF(OR($D3="买入",$D3="定投",$D3="转入",$D3="转换转入"),ROUND(($E3-$F3)/$B3,6),IF($D3="卖出",ROUND(($E3+$F3)/$B3,6),""))) | F3: =IF($E3="","",IF($D3="卖出","",0))
B4: =IF($A4="","",IFERROR(VLOOKUP($A4,全部历史净值!$A:$B,2,FALSE),"")) | C4: =IF(OR($A4="",$B4="",$D4="",$E4=""),"",IF(OR($D4="买入",$D4="定投",$D4="转入",$D4="转换转入"),ROUND(($E4-$F4)/$B4,6),IF($D4="卖出",ROUND(($E4+$F4)/$B4,6),""))) | F4: =IF($E4="","",IF($D4="卖出","",0))
B5: =IF($A5="","",IFERROR(VLOOKUP($A5,全部历史净值!$A:$B,2,FALSE),"")) | C5: =IF(OR($A5="",$B5="",$D5="",$E5=""),"",IF(OR($D5="买入",$D5="定投",$D5="转入",$D5="转换转入"),ROUND(($E5-$F5)/$B5,6),IF($D5="卖出",ROUND(($E5+$F5)/$B5,6),""))) | F5: =IF($E5="","",IF($D5="卖出","",0))
B6: =IF($A6="","",IFERROR(VLOOKUP($A6,全部历史净值!$A:$B,2,FALSE),"")) | C6: =IF(OR($A6="",$B6="",$D6="",$E6=""),"",IF(OR($D6="买入",$D6="定投",$D6="转入",$D6="转换转入"),ROUND(($E6-$F6)/$B6,6),IF($D6="卖出",ROUND(($E6+$F6)/$B6,6),""))) | F6: =IF($E6="","",IF($D6="卖出","",0))
B7: =IF($A7="","",IFERROR(VLOOKUP($A7,全部历史净值!$A:$B,2,FALSE),"")) | C7: =IF(OR($A7="",$B7="",$D7="",$E7=""),"",IF(OR($D7="买入",$D7="定投",$D7="转入",$D7="转换转入"),ROUND(($E7-$F7)/$B7,6),IF($D7="卖出",ROUND(($E7+$F7)/$B7,6),""))) | F7: =IF($E7="","",IF($D7="卖出","",0))
B8: =IF($A8="","",IFERROR(VLOOKUP($A8,全部历史净值!$A:$B,2,FALSE),"")) | C8: =IF(OR($A8="",$B8="",$D8="",$E8=""),"",IF(OR($D8="买入",$D8="定投",$D8="转入",$D8="转换转入"),ROUND(($E8-$F8)/$B8,6),IF($D8="卖出",ROUND(($E8+$F8)/$B8,6),""))) | F8: =IF($E8="","",IF($D8="卖出","",0))
B9: =IF($A9="","",IFERROR(VLOOKUP($A9,全部历史净值!$A:$B,2,FALSE),"")) | C9: =IF(OR($A9="",$B9="",$D9="",$E9=""),"",IF(OR($D9="买入",$D9="定投",$D9="转入",$D9="转换转入"),ROUND(($E9-$F9)/$B9,6),IF($D9="卖出",ROUND(($E9+$F9)/$B9,6),""))) | F9: =IF($E9="","",IF($D9="卖出","",0))
B10: =IF($A10="","",IFERROR(VLOOKUP($A10,全部历史净值!$A:$B,2,FALSE),"")) | C10: =IF(OR($A10="",$B10="",$D10="",$E10=""),"",IF(OR($D10="买入",$D10="定投",$D10="转入",$D10="转换转入"),ROUND(($E10-$F10)/$B10,6),IF($D10="卖出",ROUND(($E10+$F10)/$B10,6),""))) | F10: =IF($E10="","",IF($D10="卖出","",0))
B11: =IF($A11="","",IFERROR(VLOOKUP($A11,全部历史净值!$A:$B,2,FALSE),"")) | C11: =IF(OR($A11="",$B11="",$D11="",$E11=""),"",IF(OR($D11="买入",$D11="定投",$D11="转入",$D11="转换转入"),ROUND(($E11-$F11)/$B11,6),IF($D11="卖出",ROUND(($E11+$F11)/$B11,6),""))) | F11: =IF($E11="","",IF($D11="卖出","",0))
B12: =IF($A12="","",IFERROR(VLOOKUP($A12,全部历史净值!$A:$B,2,FALSE),"")) | C12: =IF(OR($A12="",$B12="",$D12="",$E12=""),"",IF(OR($D12="买入",$D12="定投",$D12="转入",$D12="转换转入"),ROUND(($E12-$F12)/$B12,6),IF($D12="卖出",ROUND(($E12+$F12)/$B12,6),""))) | F12: =IF($E12="","",IF($D12="卖出","",0))
B13: =IF($A13="","",IFERROR(VLOOKUP($A13,全部历史净值!$A:$B,2,FALSE),"")) | C13: =IF(OR($A13="",$B13="",$D13="",$E13=""),"",IF(OR($D13="买入",$D13="定投",$D13="转入",$D13="转换转入"),ROUND(($E13-$F13)/$B13,6),IF($D13="卖出",ROUND(($E13+$F13)/$B13,6),""))) | F13: =IF($E13="","",IF($D13="卖出","",0))
B14: =IF($A14="","",IFERROR(VLOOKUP($A14,全部历史净值!$A:$B,2,FALSE),"")) | C14: =IF(OR($A14="",$B14="",$D14="",$E14=""),"",IF(OR($D14="买入",$D14="定投",$D14="转入",$D14="转换转入"),ROUND(($E14-$F14)/$B14,6),IF($D14="卖出",ROUND(($E14+$F14)/$B14,6),""))) | F14: =IF($E14="","",IF($D14="卖出","",0))
... B101: =IF($A101="","",IFERROR(VLOOKUP($A101,全部历史净值!$A:$B,2,FALSE),"")) | C101: =IF(OR($A101="",$B101="",$D101="",$E101=""),"",IF(OR($D101="买入",$D101="定投",$D101="转入",$D101="转换转入"),ROUND(($E101-$F101)/$B101,6),IF($D101="卖出",ROUND(($E101+$F101)/$B101,6),""))) | F101: =IF($E101="","",IF($D101="卖出","",0))

Sheet 全部历史净值
A1: 日期 | B1: 净值 | C1: 日增长率
A2: 42776 | B2: 1
A3: 42783 | B3: 1.0005
A4: 42788 | B4: 1.0008
A5: 42789 | B5: 1.0009 | C5: 0.0001
A6: 42790 | B6: 1.001 | C6: 0.0001
A7: 42793 | B7: 1.0011 | C7: 0.0001
A8: 42794 | B8: 1.0012 | C8: 0.0001
A9: 42795 | B9: 1.0014 | C9: 0.0002
A10: 42796 | B10: 1.0015 | C10: 0.0001
A11: 42797 | B11: 1.0016 | C11: 0.0001
A12: 42800 | B12: 1.0021 | C12: 0.0005
A13: 42801 | B13: 1.0021 | C13: 0
A14: 42802 | B14: 1.002 | C14: -0.0001
A15: 42803 | B15: 1.0023 | C15: 0.0003
A16: 42804 | B16: 1.0022 | C16: -0.0001
... A216: 43098 | B216: 1.0294 | C216: 0.0007
A217: 43100 | B217: 1.0297
A218: 43102 | B218: 1.0315 | C218: 0.002
A219: 43103 | B219: 1.0323 | C219: 0.0008
A220: 43104 | B220: 1.0329 | C220: 0.0006
A221: 43105 | B221: 1.0338 | C221: 0.0009
A222: 43108 | B222: 1.0345 | C222: 0.0007
A223: 43109 | B223: 1.0342 | C223: -0.0003
A224: 43110 | B224: 1.0336 | C224: -0.0006
A225: 43111 | B225: 1.0332 | C225: -0.0004
A226: 43112 | B226: 1.0332 | C226: 0
A227: 43115 | B227: 1.0336 | C227: 0.0004
A228: 43116 | B228: 1.0337 | C228: 0.0001
A229: 43117 | B229: 1.0337 | C229: 0
... A336: 43280 | B336: 1.015 | C336: 0.0016
A337: 43281 | B337: 1.0151
A338: 43283 | B338: 1.0167 | C338: 0.0017
A339: 43284 | B339: 1.0177 | C339: 0.001
A340: 43285 | B340: 1.018 | C340: 0.0003
A341: 43286 | B341: 1.0193 | C341: 0.0013
A342: 43287 | B342: 1.0196 | C342: 0.0003
A343: 43290 | B343: 1.0196 | C343: 0
A344: 43291 | B344: 1.0192 | C344: -0.0004
A345: 43292 | B345: 1.0195 | C345: 0.0003
...
