Workbook

Sheet 持仓总览
B2: 华夏全球科技先锋 · 单笔交易账本
B3: 005698 / QDII A人民币 模板更新：2026-09-28 支持利润优先与本金优先两种记账模式
B5: 估值净值日期 | C5: =IF(AND(AND(ISNUMBER(C37),C37>0,C37=INT(C37),ISNUMBER(F37),F37>0),OR(NOT(AND(ISNUMBER(C19),C19>0,ISNUMBER(逐笔交易!AB506),逐笔交易!AB506>0)),C37>=C19)),C37,IF(AND(ISNUMBER(C19),C19>0,ISNUMBER(逐笔交易!AB506),逐笔交易!AB506>0),C19,"")) -> 46288 | E5: 估值单位净值 | F5: =IF(AND(AND(ISNUMBER(C37),C37>0,C37=INT(C37),ISNUMBER(F37),F37>0),OR(NOT(AND(ISNUMBER(C19),C19>0,ISNUMBER(逐笔交易!AB506),逐笔交易!AB506>0)),C37>=C19)),F37,IF(AND(ISNUMBER(C19),C19>0,ISNUMBER(逐笔交易!AB506),逐笔交易!AB506>0),逐笔交易!AB506,"")) -> 2.8398 | H5: 金额核对容差（元）
B6: 录入提示 | C6: 自动取日期较新的净值；公布净值在下方更新。 | H6: 0.1
B7: 卖出分配模式 | C7: 利润优先 | E7: 切换模式后，重算全部已确认卖出记录。
B8: =IF(逐笔交易!AA506="错误","存在录入问题，请先修正逐笔交易 I 列提示",IF(COUNTIFS(逐笔交易!I7:I506,"已计入")=0,"尚未录入可计入交易",IF(NOT(ISNUMBER(C5)),"估值日期未填写或格式无效，请检查 C5",IF(OR(C5<=0,C5<>INT(C5)),"估值日期无效，请检查 C5",IF(NOT(ISNUMBER(F5)),"估值单位净值未填写或不是数字，请检查 F5",IF(F5<=0,"估值单位净值须大于 0，请检查 F5",IF(C5<逐笔交易!Z506,"估值日期 "&TEXT(C5,"yyyy-mm-dd")&" 早于最近交易 "&TEXT(逐笔交易!Z506,"yyyy-mm-dd")&"；请核对交易日期，或更新同日净值。",IF(H19>0,"历史交易已入账；含原表估算，请核对成交单","已按录入交易更新")))))))) -> 历史交易已入账；含原表估算，请核对成交单
B10: 当前持仓 | E10: 累计收支
B11: 当前持有金额（元） | C11: =IF(AND(AND(逐笔交易!AA506="正常",COUNTIFS(逐笔交易!I7:I506,"已计入")>0),ISNUMBER(C5),ISNUMBER(F5),F5>0,C5>=逐笔交易!Z506),ROUND(逐笔交易!K506*F5,2),"") -> 97360.92 | E11: 累计投入及转入成本 | F11: =IF(AND(逐笔交易!AA506="正常",COUNTIFS(逐笔交易!I7:I506,"已计入")>0),逐笔交易!U506,"") -> 82516.01
B12: 剩余本金（元） | C12: =IF(AND(逐笔交易!AA506="正常",COUNTIFS(逐笔交易!I7:I506,"已计入")>0),逐笔交易!Q506,"") -> 82516.01 | E12: 累计收回金额（元） | F12: =IF(AND(逐笔交易!AA506="正常",COUNTIFS(逐笔交易!I7:I506,"已计入")>0),逐笔交易!V506,"") -> 0
B13: 持有盈亏（元） | C13: =IF(ISNUMBER(C11),ROUND(C11-C12,2),"") -> 14844.91 | E13: 累计提取利润（元） | F13: =IF(AND(逐笔交易!AA506="正常",COUNTIFS(逐笔交易!I7:I506,"已计入")>0),逐笔交易!W506,"") -> 0
B14: 持有盈亏比例 | C14: =IF(AND(ISNUMBER(C13),C12>0),C13/C12,"") -> 0.17990339 | E14: 累计结清亏损（元） | F14: =IF(AND(逐笔交易!AA506="正常",COUNTIFS(逐笔交易!I7:I506,"已计入")>0),逐笔交易!X506,"") -> 0
B15: 当前持有份额 | C15: =IF(AND(逐笔交易!AA506="正常",COUNTIFS(逐笔交易!I7:I506,"已计入")>0),逐笔交易!K506,"") -> 34284.43 | E15: 累计总盈亏（元） | F15: =IF(ISNUMBER(C11),ROUND(C11+F12-F11,2),"") -> 14844.91
B16: 本金状态 | C16: =IF(ISNUMBER(C15),IF(C15=0,"已清仓",IF(C12=0,"本金已收回","仍有本金")),"") -> 仍有本金 | E16: 累计收益率（非年化） | F16: =IF(AND(ISNUMBER(F15),F11>0),F15/F11,"") -> 0.17990339
B18: 已计入笔数 | C18: =COUNTIFS(逐笔交易!I7:I506,"已计入") -> 110 | E18: 待确认／待修正 | F18: =COUNTIFS(逐笔交易!G7:G506,"待确认")+COUNTIFS(逐笔交易!G7:G506,"待修正") -> 0 | H18: 含历史估算（笔）
B19: 最新成交净值日 | C19: =IF(AND(逐笔交易!AA506="正常",COUNTIFS(逐笔交易!I7:I506,"已计入")>0),逐笔交易!Z506,"") -> 46247 | E19: 收益恒等式核对 | F19: =IF(ISNUMBER(F15),IF(ABS(F15-(C13+F13-F14))<0.02,"一致","需检查"),"") -> 一致 | H19: =COUNTIFS(逐笔交易!G7:G506,"历史估算") -> 110
B21: 填写与计算口径
B22: 1. 新增买卖从第 117 行起，仅手填 A:D、F 五项黄色格；按实际成交净值日期升序填写。
B23: 2. 自动金额：买入／定投 = 份额 × 净值 + 手续费；卖出 = 份额 × 净值 − 手续费，保留到分。
B24: 3. 五项采用成交确认单数据，费用为 0 也需填写。确认份额不要再根据金额自行反推。
B25: 4. 五项录入支持买入、定投、卖出、红利再投。现金分红和转换转入需实际金额，不支持五项反推。
B26: 5. 新增记录填完五项且通过 I 列检查即计入，状态与说明自动填写；只录真实成交，不录撤单。
B27: 6. 利润优先：可提利润 = MAX(交易前市值 − 交易前本金 − 赎回费, 0)。到账先提利润，再收本金。
B28: 7. 全部赎回后，未收回的本金记为结清亏损；剩余份额与本金归零，之后买入重新累计本金。
B29: 8. 持有盈亏 = 当前市值 − 剩余本金。盈亏比例 = 持有盈亏 ÷ 剩余本金；本金为 0 时留空。
B30: 9. 累计总盈亏 = 市值 + 累计收回 − 累计投入及转入成本。累计收益率以该成本合计为分母，非年化。
B31: 10. 本金优先：卖出净到账先冲减剩余本金，超出本金才计为提取利润。现金分红仍按利润优先。
B32: 11. 同花顺界面供参考，未确认其内部收益算法。逐笔右侧显示每笔成交后的整个账户状态。
... B36: 历史 110 笔及转入成本按原表保留；已删除用户确认的 9 月 28 日试填交易，最后真实操作仍为 8 月 13 日。
B37: 公布净值日期 | C37: 46288 | E37: 公布单位净值 | F37: 2.8398
B38: 净值来源：华夏基金 https://fund.chinaamc.com/fund/005698/index.shtml（核验 2026-09-28，后续净值需更新）
B39: 公布净值栏需手动更新，不自动联网。历史数据含估算；新增金额反推可能有分位尾差，以成交单为准。

Sheet 逐笔交易
A2: 逐笔交易录入 | J2: 交易后账户明细（公式自动计算）
A3: 新增买卖仅填写黄色五项：净值日期、交易类型、成交净值、确认份额、手续费（无费用填 0）。 | J3: ="当前模式："&持仓总览!C7&"。卖出按所选模式分配；全部赎回时确认未收回本金的亏损。" -> 当前模式：利润优先。卖出按所选模式分配；全部赎回时确认未收回本金的亏损。
A4: 从第 117 行录入已成交记录，填完自动计入。历史 110 笔保留原数据；估值日期另在总览更新。
A6: 净值日期 | B6: 交易类型 | C6: 成交净值 | D6: 确认份额 | E6: 金额／历史转入成本 | F6: 手续费（元） | G6: 状态 | H6: 说明 | I6: 录入检查 | J6: 份额变动 | K6: 交易后份额 | L6: 交易前市值 | M6: 可提取利润 | N6: 本笔提取利润 | O6: 本笔收回本金 | P6: 清仓确认亏损 | Q6: 交易后本金 | R6: 交易后市值 | S6: 交易后盈亏 | T6: 交易后收益率 | U6: 累计投入及转入成本 | V6: 累计收回金额 | W6: 累计提取利润 | X6: 累计结清亏损 | Y6: 累计总盈亏 | Z6: 最近成交净值日 | AA6: 计算链状态 | AB6: 最近成交净值
A7: 45870 | B7: 买入 | C7: 1.937 | D7: 4123.9 | E7: 8000 | F7: 12 | G7: 历史估算 | H7: 原下单 2025-08-01T10:13:48 份额、费用及净值日沿用旧表估算 | I7: =IF(COUNTA(A7:H7)=0,"",IF(OR(OR(OR(G7="撤单",G7="交易失败",G7="交易关闭"),G7="交易失败",G7="交易关闭"),G7="交易失败",G7="交易关闭"),"已排除",IF(G7="待确认","待确认",IF(NOT(OR(G7="已确认",G7="历史估算")),"请选择确认状态",IF(NOT(ISNUMBER(A7)),"缺少有效净值日期",IF(OR(A7<=0,A7<>INT(A7)),"净值日期无效",IF(NOT(OR(OR(B7="买入",B7="定投",B7="转换转入"),B7="卖出",B7="现金分红",B7="红利再投")),"请选择交易类型",IF(NOT(ISNUMBER(C7)),"缺少成交净值",IF(C7<=0,"成交净值须大于零",IF(NOT(ISNUMBER(D7)),"缺少确认份额（分红填0）",IF(NOT(ISNUMBER(E7)),"缺少确认金额（再投填0）",IF(NOT(ISNUMBER(F7)),"缺少手续费（无费用填0）",IF(OR(D7<0,E7<0,F7<0),"份额金额费用不能为负",IF("正常"="错误","前行待修正",IF(A7<0,"日期需按成交顺序递增",IF(AND(B7="现金分红",OR(D7<>0,E7<=0,F7<>0)),"分红填份额0、费用0、正金额",IF(AND(B7="红利再投",OR(D7<=0,E7<>0,F7<>0)),"再投填正份额、金额0、费用0",IF(AND(OR(B7="现金分红",B7="红利再投"),0<=0),"分红或再投前须有持仓",IF(AND(OR(OR(B7="买入",B7="定投",B7="转换转入"),B7="卖出"),OR(D7<=0,E7<=0)),"买卖须填正份额、正金额",IF(AND(B7="卖出",D7>0+0.000001),"卖出份额超过持仓",IF(AND(OR(B7="买入",B7="定投",B7="转换转入"),F7>=E7),"申购费不能达到总支出",IF(NOT(ISNUMBER(持仓总览!$H$6)),"请填写金额核对容差",IF(持仓总览!$H$6<0,"金额核对容差不能为负",IF(NOT(OR(持仓总览!$C$7="利润优先",持仓总览!$C$7="本金优先")),"请选择卖出分配模式",IF(AND(OR(B7="买入",B7="定投",B7="转换转入"),ABS(E7-F7-C7*D7)>持仓总览!$H$6),"买入金额与份额净值不符",IF(AND(B7="卖出",ABS(E7+F7-C7*D7)>持仓总览!$H$6),"到账加费用与赎回市值不符","已计入")))))))))))))))))))))))))) -> 已计入 | J7: =IF(AA7="正常",IF(I7="已计入",IF(OR(OR(B7="买入",B7="定投",B7="转换转入"),B7="红利再投"),D7,IF(B7="卖出",-D7,0)),0),"") -> 4123.9 | K7: =IF(AA7="正常",ROUND(0+J7,6),"") -> 4123.9 | L7: =IF(I7="已计入",ROUND(0*C7,2),"") -> 0 | M7: =IF(I7="已计入",IF(B7="卖出",MAX(0,L7-0-F7),IF(B7="现金分红",MAX(0,L7+E7-0),0)),"") -> 0 | N7: =IF(I7="已计入",IF(AND(B7="卖出",持仓总览!$C$7="本金优先"),MAX(0,E7-0),IF(OR(B7="卖出",B7="现金分红"),MIN(E7,M7),0)),"") -> 0 | O7: =IF(I7="已计入",IF(OR(B7="卖出",B7="现金分红"),MIN(0,MAX(0,E7-N7)),0),"") -> 0 | P7: =IF(I7="已计入",IF(AND(B7="卖出",K7=0),MAX(0,0-O7),0),"") -> 0 | Q7: =IF(AA7="正常",IF(I7="已计入",ROUND(0+IF(OR(B7="买入",B7="定投",B7="转换转入"),E7,0)-O7-P7,2),0),"") -> 8000 | R7: =IF(I7="已计入",ROUND(K7*C7,2),"") -> 7987.99 | S7: =IF(I7="已计入",ROUND(R7-Q7,2),"") -> -12.01 | T7: =IF(I7="已计入",IF(Q7=0,"",S7/Q7),"") -> -0.00150125 | U7: =IF(AA7="正常",0+IF(AND(I7="已计入",OR(B7="买入",B7="定投",B7="转换转入")),E7,0),"") -> 8000 | V7: =IF(AA7="正常",0+IF(AND(I7="已计入",OR(B7="卖出",B7="现金分红")),E7,0),"") -> 0 | W7: =IF(AA7="正常",0+IF(I7="已计入",N7,0),"") -> 0 | X7: =IF(AA7="正常",0+IF(I7="已计入",P7,0),"") -> 0 | Y7: =IF(I7="已计入",ROUND(R7+V7-U7,2),"") -> -12.01 | Z7: =IF(AA7="正常",IF(I7="已计入",A7,0),"") -> 45870 | AA7: =IF(OR("正常"="错误",AND(I7<>"",I7<>"已排除",I7<>"待确认",I7<>"已计入")),"错误","正常") -> 正常 | AB7: =IF(AA7="正常",IF(I7="已计入",C7,0),"") -> 1.937
A8: 45870 | B8: 买入 | C8: 1.937 | D8: 5154.88 | E8: 10000 | F8: 15 | G8: 历史估算 | H8: 原下单 2025-08-01T14:53:00 份额、费用及净值日沿用旧表估算 | I8: =IF(COUNTA(A8:H8)=0,"",IF(OR(OR(OR(G8="撤单",G8="交易失败",G8="交易关闭"),G8="交易失败",G8="交易关闭"),G8="交易失败",G8="交易关闭"),"已排除",IF(G8="待确认","待确认",IF(NOT(OR(G8="已确认",G8="历史估算")),"请选择确认状态",IF(NOT(ISNUMBER(A8)),"缺少有效净值日期",IF(OR(A8<=0,A8<>INT(A8)),"净值日期无效",IF(NOT(OR(OR(B8="买入",B8="定投",B8="转换转入"),B8="卖出",B8="现金分红",B8="红利再投")),"请选择交易类型",IF(NOT(ISNUMBER(C8)),"缺少成交净值",IF(C8<=0,"成交净值须大于零",IF(NOT(ISNUMBER(D8)),"缺少确认份额（分红填0）",IF(NOT(ISNUMBER(E8)),"缺少确认金额（再投填0）",IF(NOT(ISNUMBER(F8)),"缺少手续费（无费用填0）",IF(OR(D8<0,E8<0,F8<0),"份额金额费用不能为负",IF(AA7="错误","前行待修正",IF(A8<Z7,"日期需按成交顺序递增",IF(AND(B8="现金分红",OR(D8<>0,E8<=0,F8<>0)),"分红填份额0、费用0、正金额",IF(AND(B8="红利再投",OR(D8<=0,E8<>0,F8<>0)),"再投填正份额、金额0、费用0",IF(AND(OR(B8="现金分红",B8="红利再投"),K7<=0),"分红或再投前须有持仓",IF(AND(OR(OR(B8="买入",B8="定投",B8="转换转入"),B8="卖出"),OR(D8<=0,E8<=0)),"买卖须填正份额、正金额",IF(AND(B8="卖出",D8>K7+0.000001),"卖出份额超过持仓",IF(AND(OR(B8="买入",B8="定投",B8="转换转入"),F8>=E8),"申购费不能达到总支出",IF(NOT(ISNUMBER(持仓总览!$H$6)),"请填写金额核对容差",IF(持仓总览!$H$6<0,"金额核对容差不能为负",IF(NOT(OR(持仓总览!$C$7="利润优先",持仓总览!$C$7="本金优先")),"请选择卖出分配模式",IF(AND(OR(B8="买入",B8="定投",B8="转换转入"),ABS(E8-F8-C8*D8)>持仓总览!$H$6),"买入金额与份额净值不符",IF(AND(B8="卖出",ABS(E8+F8-C8*D8)>持仓总览!$H$6),"到账加费用与赎回市值不符","已计入")))))))))))))))))))))))))) -> 已计入 | J8: =IF(AA8="正常",IF(I8="已计入",IF(OR(OR(B8="买入",B8="定投",B8="转换转入"),B8="红利再投"),D8,IF(B8="卖出",-D8,0)),0),"") -> 5154.88 | K8: =IF(AA8="正常",ROUND(K7+J8,6),"") -> 9278.78 | L8: =IF(I8="已计入",ROUND(K7*C8,2),"") -> 7987.99 | M8: =IF(I8="已计入",IF(B8="卖出",MAX(0,L8-Q7-F8),IF(B8="现金分红",MAX(0,L8+E8-Q7),0)),"") -> 0 | N8: =IF(I8="已计入",IF(AND(B8="卖出",持仓总览!$C$7="本金优先"),MAX(0,E8-Q7),IF(OR(B8="卖出",B8="现金分红"),MIN(E8,M8),0)),"") -> 0 | O8: =IF(I8="已计入",IF(OR(B8="卖出",B8="现金分红"),MIN(Q7,MAX(0,E8-N8)),0),"") -> 0 | P8: =IF(I8="已计入",IF(AND(B8="卖出",K8=0),MAX(0,Q7-O8),0),"") -> 0 | Q8: =IF(AA8="正常",IF(I8="已计入",ROUND(Q7+IF(OR(B8="买入",B8="定投",B8="转换转入"),E8,0)-O8-P8,2),Q7),"") -> 18000 | R8: =IF(I8="已计入",ROUND(K8*C8,2),"") -> 17973 | S8: =IF(I8="已计入",ROUND(R8-Q8,2),"") -> -27 | T8: =IF(I8="已计入",IF(Q8=0,"",S8/Q8),"") -> -0.0015 | U8: =IF(AA8="正常",U7+IF(AND(I8="已计入",OR(B8="买入",B8="定投",B8="转换转入")),E8,0),"") -> 18000 | V8: =IF(AA8="正常",V7+IF(AND(I8="已计入",OR(B8="卖出",B8="现金分红")),E8,0),"") -> 0 | W8: =IF(AA8="正常",W7+IF(I8="已计入",N8,0),"") -> 0 | X8: =IF(AA8="正常",X7+IF(I8="已计入",P8,0),"") -> 0 | Y8: =IF(I8="已计入",ROUND(R8+V8-U8,2),"") -> -27 | Z8: =IF(AA8="正常",IF(I8="已计入",A8,Z7),"") -> 45870 | AA8: =IF(OR(AA7="错误",AND(I8<>"",I8<>"已排除",I8<>"待确认",I8<>"已计入")),"错误","正常") -> 正常 | AB8: =IF(AA8="正常",IF(I8="已计入",C8,AB7),"") -> 1.937
A9: 45873 | B9: 买入 | C9: 1.9949 | D9: 1001.05 | E9: 2000 | F9: 3 | G9: 历史估算 | H9: 原下单 2025-08-04T08:27:29 份额、费用及净值日沿用旧表估算 | I9: =IF(COUNTA(A9:H9)=0,"",IF(OR(OR(OR(G9="撤单",G9="交易失败",G9="交易关闭"),G9="交易失败",G9="交易关闭"),G9="交易失败",G9="交易关闭"),"已排除",IF(G9="待确认","待确认",IF(NOT(OR(G9="已确认",G9="历史估算")),"请选择确认状态",IF(NOT(ISNUMBER(A9)),"缺少有效净值日期",IF(OR(A9<=0,A9<>INT(A9)),"净值日期无效",IF(NOT(OR(OR(B9="买入",B9="定投",B9="转换转入"),B9="卖出",B9="现金分红",B9="红利再投")),"请选择交易类型",IF(NOT(ISNUMBER(C9)),"缺少成交净值",IF(C9<=0,"成交净值须大于零",IF(NOT(ISNUMBER(D9)),"缺少确认份额（分红填0）",IF(NOT(ISNUMBER(E9)),"缺少确认金额（再投填0）",IF(NOT(ISNUMBER(F9)),"缺少手续费（无费用填0）",IF(OR(D9<0,E9<0,F9<0),"份额金额费用不能为负",IF(AA8="错误","前行待修正",IF(A9<Z8,"日期需按成交顺序递增",IF(AND(B9="现金分红",OR(D9<>0,E9<=0,F9<>0)),"分红填份额0、费用0、正金额",IF(AND(B9="红利再投",OR(D9<=0,E9<>0,F9<>0)),"再投填正份额、金额0、费用0",IF(AND(OR(B9="现金分红",B9="红利再投"),K8<=0),"分红或再投前须有持仓",IF(AND(OR(OR(B9="买入",B9="定投",B9="转换转入"),B9="卖出"),OR(D9<=0,E9<=0)),"买卖须填正份额、正金额",IF(AND(B9="卖出",D9>K8+0.000001),"卖出份额超过持仓",IF(AND(OR(B9="买入",B9="定投",B9="转换转入"),F9>=E9),"申购费不能达到总支出",IF(NOT(ISNUMBER(持仓总览!$H$6)),"请填写金额核对容差",IF(持仓总览!$H$6<0,"金额核对容差不能为负",IF(NOT(OR(持仓总览!$C$7="利润优先",持仓总览!$C$7="本金优先")),"请选择卖出分配模式",IF(AND(OR(B9="买入",B9="定投",B9="转换转入"),ABS(E9-F9-C9*D9)>持仓总览!$H$6),"买入金额与份额净值不符",IF(AND(B9="卖出",ABS(E9+F9-C9*D9)>持仓总览!$H$6),"到账加费用与赎回市值不符","已计入")))))))))))))))))))))))))) -> 已计入 | J9: =IF(AA9="正常",IF(I9="已计入",IF(OR(OR(B9="买入",B9="定投",B9="转换转入"),B9="红利再投"),D9,IF(B9="卖出",-D9,0)),0),"") -> 1001.05 | K9: =IF(AA9="正常",ROUND(K8+J9,6),"") -> 10279.83 | L9: =IF(I9="已计入",ROUND(K8*C9,2),"") -> 18510.24 | M9: =IF(I9="已计入",IF(B9="卖出",MAX(0,L9-Q8-F9),IF(B9="现金分红",MAX(0,L9+E9-Q8),0)),"") -> 0 | N9: =IF(I9="已计入",IF(AND(B9="卖出",持仓总览!$C$7="本金优先"),MAX(0,E9-Q8),IF(OR(B9="卖出",B9="现金分红"),MIN(E9,M9),0)),"") -> 0 | O9: =IF(I9="已计入",IF(OR(B9="卖出",B9="现金分红"),MIN(Q8,MAX(0,E9-N9)),0),"") -> 0 | P9: =IF(I9="已计入",IF(AND(B9="卖出",K9=0),MAX(0,Q8-O9),0),"") -> 0 | Q9: =IF(AA9="正常",IF(I9="已计入",ROUND(Q8+IF(OR(B9="买入",B9="定投",B9="转换转入"),E9,0)-O9-P9,2),Q8),"") -> 20000 | R9: =IF(I9="已计入",ROUND(K9*C9,2),"") -> 20507.23 | S9: =IF(I9="已计入",ROUND(R9-Q9,2),"") -> 507.23 | T9: =IF(I9="已计入",IF(Q9=0,"",S9/Q9),"") -> 0.0253615 | U9: =IF(AA9="正常",U8+IF(AND(I9="已计入",OR(B9="买入",B9="定投",B9="转换转入")),E9,0),"") -> 20000 | V9: =IF(AA9="正常",V8+IF(AND(I9="已计入",OR(B9="卖出",B9="现金分红")),E9,0),"") -> 0 | W9: =IF(AA9="正常",W8+IF(I9="已计入",N9,0),"") -> 0 | X9: =IF(AA9="正常",X8+IF(I9="已计入",P9,0),"") -> 0 | Y9: =IF(I9="已计入",ROUND(R9+V9-U9,2),"") -> 507.23 | Z9: =IF(AA9="正常",IF(I9="已计入",A9,Z8),"") -> 45873 | AA9: =IF(OR(AA8="错误",AND(I9<>"",I9<>"已排除",I9<>"待确认",I9<>"已计入")),"错误","正常") -> 正常 | AB9: =IF(AA9="正常",IF(I9="已计入",C9,AB8),"") -> 1.9949
A10: 45875 | B10: 买入 | C10: 2.0113 | D10: 24.82 | E10: 50 | F10: 0.08 | G10: 历史估算 | H10: 原下单 2025-08-06T09:08:01 份额、费用及净值日沿用旧表估算 | I10: =IF(COUNTA(A10:H10)=0,"",IF(OR(OR(OR(G10="撤单",G10="交易失败",G10="交易关闭"),G10="交易失败",G10="交易关闭"),G10="交易失败",G10="交易关闭"),"已排除",IF(G10="待确认","待确认",IF(NOT(OR(G10="已确认",G10="历史估算")),"请选择确认状态",IF(NOT(ISNUMBER(A10)),"缺少有效净值日期",IF(OR(A10<=0,A10<>INT(A10)),"净值日期无效",IF(NOT(OR(OR(B10="买入",B10="定投",B10="转换转入"),B10="卖出",B10="现金分红",B10="红利再投")),"请选择交易类型",IF(NOT(ISNUMBER(C10)),"缺少成交净值",IF(C10<=0,"成交净值须大于零",IF(NOT(ISNUMBER(D10)),"缺少确认份额（分红填0）",IF(NOT(ISNUMBER(E10)),"缺少确认金额（再投填0）",IF(NOT(ISNUMBER(F10)),"缺少手续费（无费用填0）",IF(OR(D10<0,E10<0,F10<0),"份额金额费用不能为负",IF(AA9="错误","前行待修正",IF(A10<Z9,"日期需按成交顺序递增",IF(AND(B10="现金分红",OR(D10<>0,E10<=0,F10<>0)),"分红填份额0、费用0、正金额",IF(AND(B10="红利再投",OR(D10<=0,E10<>0,F10<>0)),"再投填正份额、金额0、费用0",IF(AND(OR(B10="现金分红",B10="红利再投"),K9<=0),"分红或再投前须有持仓",IF(AND(OR(OR(B10="买入",B10="定投",B10="转换转入"),B10="卖出"),OR(D10<=0,E10<=0)),"买卖须填正份额、正金额",IF(AND(B10="卖出",D10>K9+0.000001),"卖出份额超过持仓",IF(AND(OR(B10="买入",B10="定投",B10="转换转入"),F10>=E10),"申购费不能达到总支出",IF(NOT(ISNUMBER(持仓总览!$H$6)),"请填写金额核对容差",IF(持仓总览!$H$6<0,"金额核对容差不能为负",IF(NOT(OR(持仓总览!$C$7="利润优先",持仓总览!$C$7="本金优先")),"请选择卖出分配模式",IF(AND(OR(B10="买入",B10="定投",B10="转换转入"),ABS(E10-F10-C10*D10)>持仓总览!$H$6),"买入金额与份额净值不符",IF(AND(B10="卖出",ABS(E10+F10-C10*D10)>持仓总览!$H$6),"到账加费用与赎回市值不符","已计入")))))))))))))))))))))))))) -> 已计入 | J10: =IF(AA10="正常",IF(I10="已计入",IF(OR(OR(B10="买入",B10="定投",B10="转换转入"),B10="红利再投"),D10,IF(B10="卖出",-D10,0)),0),"") -> 24.82 | K10: =IF(AA10="正常",ROUND(K9+J10,6),"") -> 10304.65 | L10: =IF(I10="已计入",ROUND(K9*C10,2),"") -> 20675.82 | M10: =IF(I10="已计入",IF(B10="卖出",MAX(0,L10-Q9-F10),IF(B10="现金分红",MAX(0,L10+E10-Q9),0)),"") -> 0 | N10: =IF(I10="已计入",IF(AND(B10="卖出",持仓总览!$C$7="本金优先"),MAX(0,E10-Q9),IF(OR(B10="卖出",B10="现金分红"),MIN(E10,M10),0)),"") -> 0 | O10: =IF(I10="已计入",IF(OR(B10="卖出",B10="现金分红"),MIN(Q9,MAX(0,E10-N10)),0),"") -> 0 | P10: =IF(I10="已计入",IF(AND(B10="卖出",K10=0),MAX(0,Q9-O10),0),"") -> 0 | Q10: =IF(AA10="正常",IF(I10="已计入",ROUND(Q9+IF(OR(B10="买入",B10="定投",B10="转换转入"),E10,0)-O10-P10,2),Q9),"") -> 20050 | R10: =IF(I10="已计入",ROUND(K10*C10,2),"") -> 20725.74 | S10: =IF(I10="已计入",ROUND(R10-Q10,2),"") -> 675.74 | T10: =IF(I10="已计入",IF(Q10=0,"",S10/Q10),"") -> 0.033702743 | U10: =IF(AA10="正常",U9+IF(AND(I10="已计入",OR(B10="买入",B10="定投",B10="转换转入")),E10,0),"") -> 20050 | V10: =IF(AA10="正常",V9+IF(AND(I10="已计入",OR(B10="卖出",B10="现金分红")),E10,0),"") -> 0 | W10: =IF(AA10="正常",W9+IF(I10="已计入",N10,0),"") -> 0 | X10: =IF(AA10="正常",X9+IF(I10="已计入",P10,0),"") -> 0 | Y10: =IF(I10="已计入",ROUND(R10+V10-U10,2),"") -> 675.74 | Z10: =IF(AA10="正常",IF(I10="已计入",A10,Z9),"") -> 45875 | AA10: =IF(OR(AA9="错误",AND(I10<>"",I10<>"已排除",I10<>"待确认",I10<>"已计入")),"错误","正常") -> 正常 | AB10: =IF(AA10="正常",IF(I10="已计入",C10,AB9),"") -> 2.0113
A11: 45875 | B11: 转换转入 | C11: 2.0113 | D11: 5317.96 | E11: 10696.01 | F11: 0 | G11: 历史估算 | H11: 原下单 2025-08-06T14:32:28 份额、费用及净值日沿用旧表估算 | I11: =IF(COUNTA(A11:H11)=0,"",IF(OR(OR(OR(G11="撤单",G11="交易失败",G11="交易关闭"),G11="交易失败",G11="交易关闭"),G11="交易失败",G11="交易关闭"),"已排除",IF(G11="待确认","待确认",IF(NOT(OR(G11="已确认",G11="历史估算")),"请选择确认状态",IF(NOT(ISNUMBER(A11)),"缺少有效净值日期",IF(OR(A11<=0,A11<>INT(A11)),"净值日期无效",IF(NOT(OR(OR(B11="买入",B11="定投",B11="转换转入"),B11="卖出",B11="现金分红",B11="红利再投")),"请选择交易类型",IF(NOT(ISNUMBER(C11)),"缺少成交净值",IF(C11<=0,"成交净值须大于零",IF(NOT(ISNUMBER(D11)),"缺少确认份额（分红填0）",IF(NOT(ISNUMBER(E11)),"缺少确认金额（再投填0）",IF(NOT(ISNUMBER(F11)),"缺少手续费（无费用填0）",IF(OR(D11<0,E11<0,F11<0),"份额金额费用不能为负",IF(AA10="错误","前行待修正",IF(A11<Z10,"日期需按成交顺序递增",IF(AND(B11="现金分红",OR(D11<>0,E11<=0,F11<>0)),"分红填份额0、费用0、正金额",IF(AND(B11="红利再投",OR(D11<=0,E11<>0,F11<>0)),"再投填正份额、金额0、费用0",IF(AND(OR(B11="现金分红",B11="红利再投"),K10<=0),"分红或再投前须有持仓",IF(AND(OR(OR(B11="买入",B11="定投",B11="转换转入"),B11="卖出"),OR(D11<=0,E11<=0)),"买卖须填正份额、正金额",IF(AND(B11="卖出",D11>K10+0.000001),"卖出份额超过持仓",IF(AND(OR(B11="买入",B11="定投",B11="转换转入"),F11>=E11),"申购费不能达到总支出",IF(NOT(ISNUMBER(持仓总览!$H$6)),"请填写金额核对容差",IF(持仓总览!$H$6<0,"金额核对容差不能为负",IF(NOT(OR(持仓总览!$C$7="利润优先",持仓总览!$C$7="本金优先")),"请选择卖出分配模式",IF(AND(OR(B11="买入",B11="定投",B11="转换转入"),ABS(E11-F11-C11*D11)>持仓总览!$H$6),"买入金额与份额净值不符",IF(AND(B11="卖出",ABS(E11+F11-C11*D11)>持仓总览!$H$6),"到账加费用与赎回市值不符","已计入")))))))))))))))))))))))))) -> 已计入 | J11: =IF(AA11="正常",IF(I11="已计入",IF(OR(OR(B11="买入",B11="定投",B11="转换转入"),B11="红利再投"),D11,IF(B11="卖出",-D11,0)),0),"") -> 5317.96 | K11: =IF(AA11="正常",ROUND(K10+J11,6),"") -> 15622.61 | L11: =IF(I11="已计入",ROUND(K10*C11,2),"") -> 20725.74 | M11: =IF(I11="已计入",IF(B11="卖出",MAX(0,L11-Q10-F11),IF(B11="现金分红",MAX(0,L11+E11-Q10),0)),"") -> 0 | N11: =IF(I11="已计入",IF(AND(B11="卖出",持仓总览!$C$7="本金优先"),MAX(0,E11-Q10),IF(OR(B11="卖出",B11="现金分红"),MIN(E11,M11),0)),"") -> 0 | O11: =IF(I11="已计入",IF(OR(B11="卖出",B11="现金分红"),MIN(Q10,MAX(0,E11-N11)),0),"") -> 0 | P11: =IF(I11="已计入",IF(AND(B11="卖出",K11=0),MAX(0,Q10-O11),0),"") -> 0 | Q11: =IF(AA11="正常",IF(I11="已计入",ROUND(Q10+IF(OR(B11="买入",B11="定投",B11="转换转入"),E11,0)-O11-P11,2),Q10),"") -> 30746.01 | R11: =IF(I11="已计入",ROUND(K11*C11,2),"") -> 31421.76 | S11: =IF(I11="已计入",ROUND(R11-Q11,2),"") -> 675.75 | T11: =IF(I11="已计入",IF(Q11=0,"",S11/Q11),"") -> 0.021978462 | U11: =IF(AA11="正常",U10+IF(AND(I11="已计入",OR(B11="买入",B11="定投",B11="转换转入")),E11,0),"") -> 30746.01 | V11: =IF(AA11="正常",V10+IF(AND(I11="已计入",OR(B11="卖出",B11="现金分红")),E11,0),"") -> 0 | W11: =IF(AA11="正常",W10+IF(I11="已计入",N11,0),"") -> 0 | X11: =IF(AA11="正常",X10+IF(I11="已计入",P11,0),"") -> 0 | Y11: =IF(I11="已计入",ROUND(R11+V11-U11,2),"") -> 675.75 | Z11: =IF(AA11="正常",IF(I11="已计入",A11,Z10),"") -> 45875 | AA11: =IF(OR(AA10="错误",AND(I11<>"",I11<>"已排除",I11<>"待确认",I11<>"已计入")),"错误","正常") -> 正常 | AB11: =IF(AA11="正常",IF(I11="已计入",C11,AB10),"") -> 2.0113
A12: 45919 | B12: 买入 | C12: 2.1377 | D12: 467.09 | E12: 1000 | F12: 1.5 | G12: 历史估算 | H12: 原下单 2025-09-19T08:01:23 份额、费用及净值日沿用旧表估算 | I12: =IF(COUNTA(A12:H12)=0,"",IF(OR(OR(OR(G12="撤单",G12="交易失败",G12="交易关闭"),G12="交易失败",G12="交易关闭"),G12="交易失败",G12="交易关闭"),"已排除",IF(G12="待确认","待确认",IF(NOT(OR(G12="已确认",G12="历史估算")),"请选择确认状态",IF(NOT(ISNUMBER(A12)),"缺少有效净值日期",IF(OR(A12<=0,A12<>INT(A12)),"净值日期无效",IF(NOT(OR(OR(B12="买入",B12="定投",B12="转换转入"),B12="卖出",B12="现金分红",B12="红利再投")),"请选择交易类型",IF(NOT(ISNUMBER(C12)),"缺少成交净值",IF(C12<=0,"成交净值须大于零",IF(NOT(ISNUMBER(D12)),"缺少确认份额（分红填0）",IF(NOT(ISNUMBER(E12)),"缺少确认金额（再投填0）",IF(NOT(ISNUMBER(F12)),"缺少手续费（无费用填0）",IF(OR(D12<0,E12<0,F12<0),"份额金额费用不能为负",IF(AA11="错误","前行待修正",IF(A12<Z11,"日期需按成交顺序递增",IF(AND(B12="现金分红",OR(D12<>0,E12<=0,F12<>0)),"分红填份额0、费用0、正金额",IF(AND(B12="红利再投",OR(D12<=0,E12<>0,F12<>0)),"再投填正份额、金额0、费用0",IF(AND(OR(B12="现金分红",B12="红利再投"),K11<=0),"分红或再投前须有持仓",IF(AND(OR(OR(B12="买入",B12="定投",B12="转换转入"),B12="卖出"),OR(D12<=0,E12<=0)),"买卖须填正份额、正金额",IF(AND(B12="卖出",D12>K11+0.000001),"卖出份额超过持仓",IF(AND(OR(B12="买入",B12="定投",B12="转换转入"),F12>=E12),"申购费不能达到总支出",IF(NOT(ISNUMBER(持仓总览!$H$6)),"请填写金额核对容差",IF(持仓总览!$H$6<0,"金额核对容差不能为负",IF(NOT(OR(持仓总览!$C$7="利润优先",持仓总览!$C$7="本金优先")),"请选择卖出分配模式",IF(AND(OR(B12="买入",B12="定投",B12="转换转入"),ABS(E12-F12-C12*D12)>持仓总览!$H$6),"买入金额与份额净值不符",IF(AND(B12="卖出",ABS(E12+F12-C12*D12)>持仓总览!$H$6),"到账加费用与赎回市值不符","已计入")))))))))))))))))))))))))) -> 已计入 | J12: =IF(AA12="正常",IF(I12="已计入",IF(OR(OR(B12="买入",B12="定投",B12="转换转入"),B12="红利再投"),D12,IF(B12="卖出",-D12,0)),0),"") -> 467.09 | K12: =IF(AA12="正常",ROUND(K11+J12,6),"") -> 16089.7 | L12: =IF(I12="已计入",ROUND(K11*C12,2),"") -> 33396.45 | M12: =IF(I12="已计入",IF(B12="卖出",MAX(0,L12-Q11-F12),IF(B12="现金分红",MAX(0,L12+E12-Q11),0)),"") -> 0 | N12: =IF(I12="已计入",IF(AND(B12="卖出",持仓总览!$C$7="本金优先"),MAX(0,E12-Q11),IF(OR(B12="卖出",B12="现金分红"),MIN(E12,M12),0)),"") -> 0 | O12: =IF(I12="已计入",IF(OR(B12="卖出",B12="现金分红"),MIN(Q11,MAX(0,E12-N12)),0),"") -> 0 | P12: =IF(I12="已计入",IF(AND(B12="卖出",K12=0),MAX(0,Q11-O12),0),"") -> 0 | Q12: =IF(AA12="正常",IF(I12="已计入",ROUND(Q11+IF(OR(B12="买入",B12="定投",B12="转换转入"),E12,0)-O12-P12,2),Q11),"") -> 31746.01 | R12: =IF(I12="已计入",ROUND(K12*C12,2),"") -> 34394.95 | S12: =IF(I12="已计入",ROUND(R12-Q12,2),"") -> 2648.94 | T12: =IF(I12="已计入",IF(Q12=0,"",S12/Q12),"") -> 0.083441667 | U12: =IF(AA12="正常",U11+IF(AND(I12="已计入",OR(B12="买入",B12="定投",B12="转换转入")),E12,0),"") -> 31746.01 | V12: =IF(AA12="正常",V11+IF(AND(I12="已计入",OR(B12="卖出",B12="现金分红")),E12,0),"") -> 0 | W12: =IF(AA12="正常",W11+IF(I12="已计入",N12,0),"") -> 0 | X12: =IF(AA12="正常",X11+IF(I12="已计入",P12,0),"") -> 0 | Y12: =IF(I12="已计入",ROUND(R12+V12-U12,2),"") -> 2648.94 | Z12: =IF(AA12="正常",IF(I12="已计入",A12,Z11),"") -> 45919 | AA12: =IF(OR(AA11="错误",AND(I12<>"",I12<>"已排除",I12<>"待确认",I12<>"已计入")),"错误","正常") -> 正常 | AB12: =IF(AA12="正常",IF(I12="已计入",C12,AB11),"") -> 2.1377
A13: 45940 | B13: 买入 | C13: 2.0671 | D13: 483.04 | E13: 1000 | F13: 1.5 | G13: 历史估算 | H13: 原下单 2025-10-10T14:15:47 份额、费用及净值日沿用旧表估算 | I13: =IF(COUNTA(A13:H13)=0,"",IF(OR(OR(OR(G13="撤单",G13="交易失败",G13="交易关闭"),G13="交易失败",G13="交易关闭"),G13="交易失败",G13="交易关闭"),"已排除",IF(G13="待确认","待确认",IF(NOT(OR(G13="已确认",G13="历史估算")),"请选择确认状态",IF(NOT(ISNUMBER(A13)),"缺少有效净值日期",IF(OR(A13<=0,A13<>INT(A13)),"净值日期无效",IF(NOT(OR(OR(B13="买入",B13="定投",B13="转换转入"),B13="卖出",B13="现金分红",B13="红利再投")),"请选择交易类型",IF(NOT(ISNUMBER(C13)),"缺少成交净值",IF(C13<=0,"成交净值须大于零",IF(NOT(ISNUMBER(D13)),"缺少确认份额（分红填0）",IF(NOT(ISNUMBER(E13)),"缺少确认金额（再投填0）",IF(NOT(ISNUMBER(F13)),"缺少手续费（无费用填0）",IF(OR(D13<0,E13<0,F13<0),"份额金额费用不能为负",IF(AA12="错误","前行待修正",IF(A13<Z12,"日期需按成交顺序递增",IF(AND(B13="现金分红",OR(D13<>0,E13<=0,F13<>0)),"分红填份额0、费用0、正金额",IF(AND(B13="红利再投",OR(D13<=0,E13<>0,F13<>0)),"再投填正份额、金额0、费用0",IF(AND(OR(B13="现金分红",B13="红利再投"),K12<=0),"分红或再投前须有持仓",IF(AND(OR(OR(B13="买入",B13="定投",B13="转换转入"),B13="卖出"),OR(D13<=0,E13<=0)),"买卖须填正份额、正金额",IF(AND(B13="卖出",D13>K12+0.000001),"卖出份额超过持仓",IF(AND(OR(B13="买入",B13="定投",B13="转换转入"),F13>=E13),"申购费不能达到总支出",IF(NOT(ISNUMBER(持仓总览!$H$6)),"请填写金额核对容差",IF(持仓总览!$H$6<0,"金额核对容差不能为负",IF(NOT(OR(持仓总览!$C$7="利润优先",持仓总览!$C$7="本金优先")),"请选择卖出分配模式",IF(AND(OR(B13="买入",B13="定投",B13="转换转入"),ABS(E13-F13-C13*D13)>持仓总览!$H$6),"买入金额与份额净值不符",IF(AND(B13="卖出",ABS(E13+F13-C13*D13)>持仓总览!$H$6),"到账加费用与赎回市值不符","已计入")))))))))))))))))))))))))) -> 已计入 | J13: =IF(AA13="正常",IF(I13="已计入",IF(OR(OR(B13="买入",B13="定投",B13="转换转入"),B13="红利再投"),D13,IF(B13="卖出",-D13,0)),0),"") -> 483.04 | K13: =IF(AA13="正常",ROUND(K12+J13,6),"") -> 16572.74 | L13: =IF(I13="已计入",ROUND(K12*C13,2),"") -> 33259.02 | M13: =IF(I13="已计入",IF(B13="卖出",MAX(0,L13-Q12-F13),IF(B13="现金分红",MAX(0,L13+E13-Q12),0)),"") -> 0 | N13: =IF(I13="已计入",IF(AND(B13="卖出",持仓总览!$C$7="本金优先"),MAX(0,E13-Q12),IF(OR(B13="卖出",B13="现金分红"),MIN(E13,M13),0)),"") -> 0 | O13: =IF(I13="已计入",IF(OR(B13="卖出",B13="现金分红"),MIN(Q12,MAX(0,E13-N13)),0),"") -> 0 | P13: =IF(I13="已计入",IF(AND(B13="卖出",K13=0),MAX(0,Q12-O13),0),"") -> 0 | Q13: =IF(AA13="正常",IF(I13="已计入",ROUND(Q12+IF(OR(B13="买入",B13="定投",B13="转换转入"),E13,0)-O13-P13,2),Q12),"") -> 32746.01 | R13: =IF(I13="已计入",ROUND(K13*C13,2),"") -> 34257.51 | S13: =IF(I13="已计入",ROUND(R13-Q13,2),"") -> 1511.5 | T13: =IF(I13="已计入",IF(Q13=0,"",S13/Q13),"") -> 0.046158295 | U13: =IF(AA13="正常",U12+IF(AND(I13="已计入",OR(B13="买入",B13="定投",B13="转换转入")),E13,0),"") -> 32746.01 | V13: =IF(AA13="正常",V12+IF(AND(I13="已计入",OR(B13="卖出",B13="现金分红")),E13,0),"") -> 0 | W13: =IF(AA13="正常",W12+IF(I13="已计入",N13,0),"") -> 0 | X13: =IF(AA13="正常",X12+IF(I13="已计入",P13,0),"") -> 0 | Y13: =IF(I13="已计入",ROUND(R13+V13-U13,2),"") -> 1511.5 | Z13: =IF(AA13="正常",IF(I13="已计入",A13,Z12),"") -> 45940 | AA13: =IF(OR(AA12="错误",AND(I13<>"",I13<>"已排除",I13<>"待确认",I13<>"已计入")),"错误","正常") -> 正常 | AB13: =IF(AA13="正常",IF(I13="已计入",C13,AB12),"") -> 2.0671
A14: 45964 | B14: 定投 | C14: 2.2572 | D14: 132.71 | E14: 300 | F14: 0.45 | G14: 历史估算 | H14: 原下单 2025-11-03T10:13:33 份额、费用及净值日沿用旧表估算 | I14: =IF(COUNTA(A14:H14)=0,"",IF(OR(OR(OR(G14="撤单",G14="交易失败",G14="交易关闭"),G14="交易失败",G14="交易关闭"),G14="交易失败",G14="交易关闭"),"已排除",IF(G14="待确认","待确认",IF(NOT(OR(G14="已确认",G14="历史估算")),"请选择确认状态",IF(NOT(ISNUMBER(A14)),"缺少有效净值日期",IF(OR(A14<=0,A14<>INT(A14)),"净值日期无效",IF(NOT(OR(OR(B14="买入",B14="定投",B14="转换转入"),B14="卖出",B14="现金分红",B14="红利再投")),"请选择交易类型",IF(NOT(ISNUMBER(C14)),"缺少成交净值",IF(C14<=0,"成交净值须大于零",IF(NOT(ISNUMBER(D14)),"缺少确认份额（分红填0）",IF(NOT(ISNUMBER(E14)),"缺少确认金额（再投填0）",IF(NOT(ISNUMBER(F14)),"缺少手续费（无费用填0）",IF(OR(D14<0,E14<0,F14<0),"份额金额费用不能为负",IF(AA13="错误","前行待修正",IF(A14<Z13,"日期需按成交顺序递增",IF(AND(B14="现金分红",OR(D14<>0,E14<=0,F14<>0)),"分红填份额0、费用0、正金额",IF(AND(B14="红利再投",OR(D14<=0,E14<>0,F14<>0)),"再投填正份额、金额0、费用0",IF(AND(OR(B14="现金分红",B14="红利再投"),K13<=0),"分红或再投前须有持仓",IF(AND(OR(OR(B14="买入",B14="定投",B14="转换转入"),B14="卖出"),OR(D14<=0,E14<=0)),"买卖须填正份额、正金额",IF(AND(B14="卖出",D14>K13+0.000001),"卖出份额超过持仓",IF(AND(OR(B14="买入",B14="定投",B14="转换转入"),F14>=E14),"申购费不能达到总支出",IF(NOT(ISNUMBER(持仓总览!$H$6)),"请填写金额核对容差",IF(持仓总览!$H$6<0,"金额核对容差不能为负",IF(NOT(OR(持仓总览!$C$7="利润优先",持仓总览!$C$7="本金优先")),"请选择卖出分配模式",IF(AND(OR(B14="买入",B14="定投",B14="转换转入"),ABS(E14-F14-C14*D14)>持仓总览!$H$6),"买入金额与份额净值不符",IF(AND(B14="卖出",ABS(E14+F14-C14*D14)>持仓总览!$H$6),"到账加费用与赎回市值不符","已计入")))))))))))))))))))))))))) -> 已计入 | J14: =IF(AA14="正常",IF(I14="已计入",IF(OR(OR(B14="买入",B14="定投",B14="转换转入"),B14="红利再投"),D14,IF(B14="卖出",-D14,0)),0),"") -> 132.71 | K14: =IF(AA14="正常",ROUND(K13+J14,6),"") -> 16705.45 | L14: =IF(I14="已计入",ROUND(K13*C14,2),"") -> 37407.99 | M14: =IF(I14="已计入",IF(B14="卖出",MAX(0,L14-Q13-F14),IF(B14="现金分红",MAX(0,L14+E14-Q13),0)),"") -> 0 | N14: =IF(I14="已计入",IF(AND(B14="卖出",持仓总览!$C$7="本金优先"),MAX(0,E14-Q13),IF(OR(B14="卖出",B14="现金分红"),MIN(E14,M14),0)),"") -> 0 | O14: =IF(I14="已计入",IF(OR(B14="卖出",B14="现金分红"),MIN(Q13,MAX(0,E14-N14)),0),"") -> 0 | P14: =IF(I14="已计入",IF(AND(B14="卖出",K14=0),MAX(0,Q13-O14),0),"") -> 0 | Q14: =IF(AA14="正常",IF(I14="已计入",ROUND(Q13+IF(OR(B14="买入",B14="定投",B14="转换转入"),E14,0)-O14-P14,2),Q13),"") -> 33046.01 | R14: =IF(I14="已计入",ROUND(K14*C14,2),"") -> 37707.54 | S14: =IF(I14="已计入",ROUND(R14-Q14,2),"") -> 4661.53 | T14: =IF(I14="已计入",IF(Q14=0,"",S14/Q14),"") -> 0.14106181 | U14: =IF(AA14="正常",U13+IF(AND(I14="已计入",OR(B14="买入",B14="定投",B14="转换转入")),E14,0),"") -> 33046.01 | V14: =IF(AA14="正常",V13+IF(AND(I14="已计入",OR(B14="卖出",B14="现金分红")),E14,0),"") -> 0 | W14: =IF(AA14="正常",W13+IF(I14="已计入",N14,0),"") -> 0 | X14: =IF(AA14="正常",X13+IF(I14="已计入",P14,0),"") -> 0 | Y14: =IF(I14="已计入",ROUND(R14+V14-U14,2),"") -> 4661.53 | Z14: =IF(AA14="正常",IF(I14="已计入",A14,Z13),"") -> 45964 | AA14: =IF(OR(AA13="错误",AND(I14<>"",I14<>"已排除",I14<>"待确认",I14<>"已计入")),"错误","正常") -> 正常 | AB14: =IF(AA14="正常",IF(I14="已计入",C14,AB13),"") -> 2.2572
A15: 45965 | B15: 买入 | C15: 2.1901 | D15: 136.77 | E15: 300 | F15: 0.45 | G15: 历史估算 | H15: 原下单 2025-11-04T11:06:31 份额、费用及净值日沿用旧表估算 | I15: =IF(COUNTA(A15:H15)=0,"",IF(OR(OR(OR(G15="撤单",G15="交易失败",G15="交易关闭"),G15="交易失败",G15="交易关闭"),G15="交易失败",G15="交易关闭"),"已排除",IF(G15="待确认","待确认",IF(NOT(OR(G15="已确认",G15="历史估算")),"请选择确认状态",IF(NOT(ISNUMBER(A15)),"缺少有效净值日期",IF(OR(A15<=0,A15<>INT(A15)),"净值日期无效",IF(NOT(OR(OR(B15="买入",B15="定投",B15="转换转入"),B15="卖出",B15="现金分红",B15="红利再投")),"请选择交易类型",IF(NOT(ISNUMBER(C15)),"缺少成交净值",IF(C15<=0,"成交净值须大于零",IF(NOT(ISNUMBER(D15)),"缺少确认份额（分红填0）",IF(NOT(ISNUMBER(E15)),"缺少确认金额（再投填0）",IF(NOT(ISNUMBER(F15)),"缺少手续费（无费用填0）",IF(OR(D15<0,E15<0,F15<0),"份额金额费用不能为负",IF(AA14="错误","前行待修正",IF(A15<Z14,"日期需按成交顺序递增",IF(AND(B15="现金分红",OR(D15<>0,E15<=0,F15<>0)),"分红填份额0、费用0、正金额",IF(AND(B15="红利再投",OR(D15<=0,E15<>0,F15<>0)),"再投填正份额、金额0、费用0",IF(AND(OR(B15="现金分红",B15="红利再投"),K14<=0),"分红或再投前须有持仓",IF(AND(OR(OR(B15="买入",B15="定投",B15="转换转入"),B15="卖出"),OR(D15<=0,E15<=0)),"买卖须填正份额、正金额",IF(AND(B15="卖出",D15>K14+0.000001),"卖出份额超过持仓",IF(AND(OR(B15="买入",B15="定投",B15="转换转入"),F15>=E15),"申购费不能达到总支出",IF(NOT(ISNUMBER(持仓总览!$H$6)),"请填写金额核对容差",IF(持仓总览!$H$6<0,"金额核对容差不能为负",IF(NOT(OR(持仓总览!$C$7="利润优先",持仓总览!$C$7="本金优先")),"请选择卖出分配模式",IF(AND(OR(B15="买入",B15="定投",B15="转换转入"),ABS(E15-F15-C15*D15)>持仓总览!$H$6),"买入金额与份额净值不符",IF(AND(B15="卖出",ABS(E15+F15-C15*D15)>持仓总览!$H$6),"到账加费用与赎回市值不符","已计入")))))))))))))))))))))))))) -> 已计入 | J15: =IF(AA15="正常",IF(I15="已计入",IF(OR(OR(B15="买入",B15="定投",B15="转换转入"),B15="红利再投"),D15,IF(B15="卖出",-D15,0)),0),"") -> 136.77 | K15: =IF(AA15="正常",ROUND(K14+J15,6),"") -> 16842.22 | L15: =IF(I15="已计入",ROUND(K14*C15,2),"") -> 36586.61 | M15: =IF(I15="已计入",IF(B15="卖出",MAX(0,L15-Q14-F15),IF(B15="现金分红",MAX(0,L15+E15-Q14),0)),"") -> 0 | N15: =IF(I15="已计入",IF(AND(B15="卖出",持仓总览!$C$7="本金优先"),MAX(0,E15-Q14),IF(OR(B15="卖出",B15="现金分红"),MIN(E15,M15),0)),"") -> 0 | O15: =IF(I15="已计入",IF(OR(B15="卖出",B15="现金分红"),MIN(Q14,MAX(0,E15-N15)),0),"") -> 0 | P15: =IF(I15="已计入",IF(AND(B15="卖出",K15=0),MAX(0,Q14-O15),0),"") -> 0 | Q15: =IF(AA15="正常",IF(I15="已计入",ROUND(Q14+IF(OR(B15="买入",B15="定投",B15="转换转入"),E15,0)-O15-P15,2),Q14),"") -> 33346.01 | R15: =IF(I15="已计入",ROUND(K15*C15,2),"") -> 36886.15 | S15: =IF(I15="已计入",ROUND(R15-Q15,2),"") -> 3540.14 | T15: =IF(I15="已计入",IF(Q15=0,"",S15/Q15),"") -> 0.10616383 | U15: =IF(AA15="正常",U14+IF(AND(I15="已计入",OR(B15="买入",B15="定投",B15="转换转入")),E15,0),"") -> 33346.01 | V15: =IF(AA15="正常",V14+IF(AND(I15="已计入",OR(B15="卖出",B15="现金分红")),E15,0),"") -> 0 | W15: =IF(AA15="正常",W14+IF(I15="已计入",N15,0),"") -> 0 | X15: =IF(AA15="正常",X14+IF(I15="已计入",P15,0),"") -> 0 | Y15: =IF(I15="已计入",ROUND(R15+V15-U15,2),"") -> 3540.14 | Z15: =IF(AA15="正常",IF(I15="已计入",A15,Z14),"") -> 45965 | AA15: =IF(OR(AA14="错误",AND(I15<>"",I15<>"已排除",I15<>"待确认",I15<>"已计入")),"错误","正常") -> 正常 | AB15: =IF(AA15="正常",IF(I15="已计入",C15,AB14),"") -> 2.1901
A16: 45966 | B16: 定投 | C16: 2.2152 | D16: 135.22 | E16: 300 | F16: 0.45 | G16: 历史估算 | H16: 原下单 2025-11-05T10:05:15 份额、费用及净值日沿用旧表估算 | I16: =IF(COUNTA(A16:H16)=0,"",IF(OR(OR(OR(G16="撤单",G16="交易失败",G16="交易关闭"),G16="交易失败",G16="交易关闭"),G16="交易失败",G16="交易关闭"),"已排除",IF(G16="待确认","待确认",IF(NOT(OR(G16="已确认",G16="历史估算")),"请选择确认状态",IF(NOT(ISNUMBER(A16)),"缺少有效净值日期",IF(OR(A16<=0,A16<>INT(A16)),"净值日期无效",IF(NOT(OR(OR(B16="买入",B16="定投",B16="转换转入"),B16="卖出",B16="现金分红",B16="红利再投")),"请选择交易类型",IF(NOT(ISNUMBER(C16)),"缺少成交净值",IF(C16<=0,"成交净值须大于零",IF(NOT(ISNUMBER(D16)),"缺少确认份额（分红填0）",IF(NOT(ISNUMBER(E16)),"缺少确认金额（再投填0）",IF(NOT(ISNUMBER(F16)),"缺少手续费（无费用填0）",IF(OR(D16<0,E16<0,F16<0),"份额金额费用不能为负",IF(AA15="错误","前行待修正",IF(A16<Z15,"日期需按成交顺序递增",IF(AND(B16="现金分红",OR(D16<>0,E16<=0,F16<>0)),"分红填份额0、费用0、正金额",IF(AND(B16="红利再投",OR(D16<=0,E16<>0,F16<>0)),"再投填正份额、金额0、费用0",IF(AND(OR(B16="现金分红",B16="红利再投"),K15<=0),"分红或再投前须有持仓",IF(AND(OR(OR(B16="买入",B16="定投",B16="转换转入"),B16="卖出"),OR(D16<=0,E16<=0)),"买卖须填正份额、正金额",IF(AND(B16="卖出",D16>K15+0.000001),"卖出份额超过持仓",IF(AND(OR(B16="买入",B16="定投",B16="转换转入"),F16>=E16),"申购费不能达到总支出",IF(NOT(ISNUMBER(持仓总览!$H$6)),"请填写金额核对容差",IF(持仓总览!$H$6<0,"金额核对容差不能为负",IF(NOT(OR(持仓总览!$C$7="利润优先",持仓总览!$C$7="本金优先")),"请选择卖出分配模式",IF(AND(OR(B16="买入",B16="定投",B16="转换转入"),ABS(E16-F16-C16*D16)>持仓总览!$H$6),"买入金额与份额净值不符",IF(AND(B16="卖出",ABS(E16+F16-C16*D16)>持仓总览!$H$6),"到账加费用与赎回市值不符","已计入")))))))))))))))))))))))))) -> 已计入 | J16: =IF(AA16="正常",IF(I16="已计入",IF(OR(OR(B16="买入",B16="定投",B16="转换转入"),B16="红利再投"),D16,IF(B16="卖出",-D16,0)),0),"") -> 135.22 | K16: =IF(AA16="正常",ROUND(K15+J16,6),"") -> 16977.44 | L16: =IF(I16="已计入",ROUND(K15*C16,2),"") -> 37308.89 | M16: =IF(I16="已计入",IF(B16="卖出",MAX(0,L16-Q15-F16),IF(B16="现金分红",MAX(0,L16+E16-Q15),0)),"") -> 0 | N16: =IF(I16="已计入",IF(AND(B16="卖出",持仓总览!$C$7="本金优先"),MAX(0,E16-Q15),IF(OR(B16="卖出",B16="现金分红"),MIN(E16,M16),0)),"") -> 0 | O16: =IF(I16="已计入",IF(OR(B16="卖出",B16="现金分红"),MIN(Q15,MAX(0,E16-N16)),0),"") -> 0 | P16: =IF(I16="已计入",IF(AND(B16="卖出",K16=0),MAX(0,Q15-O16),0),"") -> 0 | Q16: =IF(AA16="正常",IF(I16="已计入",ROUND(Q15+IF(OR(B16="买入",B16="定投",B16="转换转入"),E16,0)-O16-P16,2),Q15),"") -> 33646.01 | R16: =IF(I16="已计入",ROUND(K16*C16,2),"") -> 37608.43 | S16: =IF(I16="已计入",ROUND(R16-Q16,2),"") -> 3962.42 | T16: =IF(I16="已计入",IF(Q16=0,"",S16/Q16),"") -> 0.1177679 | U16: =IF(AA16="正常",U15+IF(AND(I16="已计入",OR(B16="买入",B16="定投",B16="转换转入")),E16,0),"") -> 33646.01 | V16: =IF(AA16="正常",V15+IF(AND(I16="已计入",OR(B16="卖出",B16="现金分红")),E16,0),"") -> 0 | W16: =IF(AA16="正常",W15+IF(I16="已计入",N16,0),"") -> 0 | X16: =IF(AA16="正常",X15+IF(I16="已计入",P16,0),"") -> 0 | Y16: =IF(I16="已计入",ROUND(R16+V16-U16,2),"") -> 3962.42 | Z16: =IF(AA16="正常",IF(I16="已计入",A16,Z15),"") -> 45966 | AA16: =IF(OR(AA15="错误",AND(I16<>"",I16<>"已排除",I16<>"待确认",I16<>"已计入")),"错误","正常") -> 正常 | AB16: =IF(AA16="正常",IF(I16="已计入",C16,AB15),"") -> 2.2152
A17: 46003 | B17: 定投 | C17: 2.1506 | D17: 46.43 | E17: 100 | F17: 0.15 | G17: 历史估算 | H17: 原下单 2025-12-12T10:16:18 份额、费用及净值日沿用旧表估算 | I17: =IF(COUNTA(A17:H17)=0,"",IF(OR(OR(OR(G17="撤单",G17="交易失败",G17="交易关闭"),G17="交易失败",G17="交易关闭"),G17="交易失败",G17="交易关闭"),"已排除",IF(G17="待确认","待确认",IF(NOT(OR(G17="已确认",G17="历史估算")),"请选择确认状态",IF(NOT(ISNUMBER(A17)),"缺少有效净值日期",IF(OR(A17<=0,A17<>INT(A17)),"净值日期无效",IF(NOT(OR(OR(B17="买入",B17="定投",B17="转换转入"),B17="卖出",B17="现金分红",B17="红利再投")),"请选择交易类型",IF(NOT(ISNUMBER(C17)),"缺少成交净值",IF(C17<=0,"成交净值须大于零",IF(NOT(ISNUMBER(D17)),"缺少确认份额（分红填0）",IF(NOT(ISNUMBER(E17)),"缺少确认金额（再投填0）",IF(NOT(ISNUMBER(F17)),"缺少手续费（无费用填0）",IF(OR(D17<0,E17<0,F17<0),"份额金额费用不能为负",IF(AA16="错误","前行待修正",IF(A17<Z16,"日期需按成交顺序递增",IF(AND(B17="现金分红",OR(D17<>0,E17<=0,F17<>0)),"分红填份额0、费用0、正金额",IF(AND(B17="红利再投",OR(D17<=0,E17<>0,F17<>0)),"再投填正份额、金额0、费用0",IF(AND(OR(B17="现金分红",B17="红利再投"),K16<=0),"分红或再投前须有持仓",IF(AND(OR(OR(B17="买入",B17="定投",B17="转换转入"),B17="卖出"),OR(D17<=0,E17<=0)),"买卖须填正份额、正金额",IF(AND(B17="卖出",D17>K16+0.000001),"卖出份额超过持仓",IF(AND(OR(B17="买入",B17="定投",B17="转换转入"),F17>=E17),"申购费不能达到总支出",IF(NOT(ISNUMBER(持仓总览!$H$6)),"请填写金额核对容差",IF(持仓总览!$H$6<0,"金额核对容差不能为负",IF(NOT(OR(持仓总览!$C$7="利润优先",持仓总览!$C$7="本金优先")),"请选择卖出分配模式",IF(AND(OR(B17="买入",B17="定投",B17="转换转入"),ABS(E17-F17-C17*D17)>持仓总览!$H$6),"买入金额与份额净值不符",IF(AND(B17="卖出",ABS(E17+F17-C17*D17)>持仓总览!$H$6),"到账加费用与赎回市值不符","已计入")))))))))))))))))))))))))) -> 已计入 | J17: =IF(AA17="正常",IF(I17="已计入",IF(OR(OR(B17="买入",B17="定投",B17="转换转入"),B17="红利再投"),D17,IF(B17="卖出",-D17,0)),0),"") -> 46.43 | K17: =IF(AA17="正常",ROUND(K16+J17,6),"") -> 17023.87 | L17: =IF(I17="已计入",ROUND(K16*C17,2),"") -> 36511.68 | M17: =IF(I17="已计入",IF(B17="卖出",MAX(0,L17-Q16-F17),IF(B17="现金分红",MAX(0,L17+E17-Q16),0)),"") -> 0 | N17: =IF(I17="已计入",IF(AND(B17="卖出",持仓总览!$C$7="本金优先"),MAX(0,E17-Q16),IF(OR(B17="卖出",B17="现金分红"),MIN(E17,M17),0)),"") -> 0 | O17: =IF(I17="已计入",IF(OR(B17="卖出",B17="现金分红"),MIN(Q16,MAX(0,E17-N17)),0),"") -> 0 | P17: =IF(I17="已计入",IF(AND(B17="卖出",K17=0),MAX(0,Q16-O17),0),"") -> 0 | Q17: =IF(AA17="正常",IF(I17="已计入",ROUND(Q16+IF(OR(B17="买入",B17="定投",B17="转换转入"),E17,0)-O17-P17,2),Q16),"") -> 33746.01 | R17: =IF(I17="已计入",ROUND(K17*C17,2),"") -> 36611.53 | S17: =IF(I17="已计入",ROUND(R17-Q17,2),"") -> 2865.52 | T17: =IF(I17="已计入",IF(Q17=0,"",S17/Q17),"") -> 0.084914335 | U17: =IF(AA17="正常",U16+IF(AND(I17="已计入",OR(B17="买入",B17="定投",B17="转换转入")),E17,0),"") -> 33746.01 | V17: =IF(AA17="正常",V16+IF(AND(I17="已计入",OR(B17="卖出",B17="现金分红")),E17,0),"") -> 0 | W17: =IF(AA17="正常",W16+IF(I17="已计入",N17,0),"") -> 0 | X17: =IF(AA17="正常",X16+IF(I17="已计入",P17,0),"") -> 0 | Y17: =IF(I17="已计入",ROUND(R17+V17-U17,2),"") -> 2865.52 | Z17: =IF(AA17="正常",IF(I17="已计入",A17,Z16),"") -> 46003 | AA17: =IF(OR(AA16="错误",AND(I17<>"",I17<>"已排除",I17<>"待确认",I17<>"已计入")),"错误","正常") -> 正常 | AB17: =IF(AA17="正常",IF(I17="已计入",C17,AB16),"") -> 2.1506
A18: 46006 | B18: 定投 | C18: 2.1177 | D18: 94.3 | E18: 200 | F18: 0.3 | G18: 历史估算 | H18: 原下单 2025-12-15T10:22:03 份额、费用及净值日沿用旧表估算 | I18: =IF(COUNTA(A18:H18)=0,"",IF(OR(OR(OR(G18="撤单",G18="交易失败",G18="交易关闭"),G18="交易失败",G18="交易关闭"),G18="交易失败",G18="交易关闭"),"已排除",IF(G18="待确认","待确认",IF(NOT(OR(G18="已确认",G18="历史估算")),"请选择确认状态",IF(NOT(ISNUMBER(A18)),"缺少有效净值日期",IF(OR(A18<=0,A18<>INT(A18)),"净值日期无效",IF(NOT(OR(OR(B18="买入",B18="定投",B18="转换转入"),B18="卖出",B18="现金分红",B18="红利再投")),"请选择交易类型",IF(NOT(ISNUMBER(C18)),"缺少成交净值",IF(C18<=0,"成交净值须大于零",IF(NOT(ISNUMBER(D18)),"缺少确认份额（分红填0）",IF(NOT(ISNUMBER(E18)),"缺少确认金额（再投填0）",IF(NOT(ISNUMBER(F18)),"缺少手续费（无费用填0）",IF(OR(D18<0,E18<0,F18<0),"份额金额费用不能为负",IF(AA17="错误","前行待修正",IF(A18<Z17,"日期需按成交顺序递增",IF(AND(B18="现金分红",OR(D18<>0,E18<=0,F18<>0)),"分红填份额0、费用0、正金额",IF(AND(B18="红利再投",OR(D18<=0,E18<>0,F18<>0)),"再投填正份额、金额0、费用0",IF(AND(OR(B18="现金分红",B18="红利再投"),K17<=0),"分红或再投前须有持仓",IF(AND(OR(OR(B18="买入",B18="定投",B18="转换转入"),B18="卖出"),OR(D18<=0,E18<=0)),"买卖须填正份额、正金额",IF(AND(B18="卖出",D18>K17+0.000001),"卖出份额超过持仓",IF(AND(OR(B18="买入",B18="定投",B18="转换转入"),F18>=E18),"申购费不能达到总支出",IF(NOT(ISNUMBER(持仓总览!$H$6)),"请填写金额核对容差",IF(持仓总览!$H$6<0,"金额核对容差不能为负",IF(NOT(OR(持仓总览!$C$7="利润优先",持仓总览!$C$7="本金优先")),"请选择卖出分配模式",IF(AND(OR(B18="买入",B18="定投",B18="转换转入"),ABS(E18-F18-C18*D18)>持仓总览!$H$6),"买入金额与份额净值不符",IF(AND(B18="卖出",ABS(E18+F18-C18*D18)>持仓总览!$H$6),"到账加费用与赎回市值不符","已计入")))))))))))))))))))))))))) -> 已计入 | J18: =IF(AA18="正常",IF(I18="已计入",IF(OR(OR(B18="买入",B18="定投",B18="转换转入"),B18="红利再投"),D18,IF(B18="卖出",-D18,0)),0),"") -> 94.3 | K18: =IF(AA18="正常",ROUND(K17+J18,6),"") -> 17118.17 | L18: =IF(I18="已计入",ROUND(K17*C18,2),"") -> 36051.45 | M18: =IF(I18="已计入",IF(B18="卖出",MAX(0,L18-Q17-F18),IF(B18="现金分红",MAX(0,L18+E18-Q17),0)),"") -> 0 | N18: =IF(I18="已计入",IF(AND(B18="卖出",持仓总览!$C$7="本金优先"),MAX(0,E18-Q17),IF(OR(B18="卖出",B18="现金分红"),MIN(E18,M18),0)),"") -> 0 | O18: =IF(I18="已计入",IF(OR(B18="卖出",B18="现金分红"),MIN(Q17,MAX(0,E18-N18)),0),"") -> 0 | P18: =IF(I18="已计入",IF(AND(B18="卖出",K18=0),MAX(0,Q17-O18),0),"") -> 0 | Q18: =IF(AA18="正常",IF(I18="已计入",ROUND(Q17+IF(OR(B18="买入",B18="定投",B18="转换转入"),E18,0)-O18-P18,2),Q17),"") -> 33946.01 | R18: =IF(I18="已计入",ROUND(K18*C18,2),"") -> 36251.15 | S18: =IF(I18="已计入",ROUND(R18-Q18,2),"") -> 2305.14 | T18: =IF(I18="已计入",IF(Q18=0,"",S18/Q18),"") -> 0.067906066 | U18: =IF(AA18="正常",U17+IF(AND(I18="已计入",OR(B18="买入",B18="定投",B18="转换转入")),E18,0),"") -> 33946.01 | V18: =IF(AA18="正常",V17+IF(AND(I18="已计入",OR(B18="卖出",B18="现金分红")),E18,0),"") -> 0 | W18: =IF(AA18="正常",W17+IF(I18="已计入",N18,0),"") -> 0 | X18: =IF(AA18="正常",X17+IF(I18="已计入",P18,0),"") -> 0 | Y18: =IF(I18="已计入",ROUND(R18+V18-U18,2),"") -> 2305.14 | Z18: =IF(AA18="正常",IF(I18="已计入",A18,Z17),"") -> 46006 | AA18: =IF(OR(AA17="错误",AND(I18<>"",I18<>"已排除",I18<>"待确认",I18<>"已计入")),"错误","正常") -> 正常 | AB18: =IF(AA18="正常",IF(I18="已计入",C18,AB17),"") -> 2.1177
A19: 46007 | B19: 定投 | C19: 2.1043 | D19: 94.9 | E19: 200 | F19: 0.3 | G19: 历史估算 | H19: 原下单 2025-12-16T10:16:25 份额、费用及净值日沿用旧表估算 | I19: =IF(COUNTA(A19:H19)=0,"",IF(OR(OR(OR(G19="撤单",G19="交易失败",G19="交易关闭"),G19="交易失败",G19="交易关闭"),G19="交易失败",G19="交易关闭"),"已排除",IF(G19="待确认","待确认",IF(NOT(OR(G19="已确认",G19="历史估算")),"请选择确认状态",IF(NOT(ISNUMBER(A19)),"缺少有效净值日期",IF(OR(A19<=0,A19<>INT(A19)),"净值日期无效",IF(NOT(OR(OR(B19="买入",B19="定投",B19="转换转入"),B19="卖出",B19="现金分红",B19="红利再投")),"请选择交易类型",IF(NOT(ISNUMBER(C19)),"缺少成交净值",IF(C19<=0,"成交净值须大于零",IF(NOT(ISNUMBER(D19)),"缺少确认份额（分红填0）",IF(NOT(ISNUMBER(E19)),"缺少确认金额（再投填0）",IF(NOT(ISNUMBER(F19)),"缺少手续费（无费用填0）",IF(OR(D19<0,E19<0,F19<0),"份额金额费用不能为负",IF(AA18="错误","前行待修正",IF(A19<Z18,"日期需按成交顺序递增",IF(AND(B19="现金分红",OR(D19<>0,E19<=0,F19<>0)),"分红填份额0、费用0、正金额",IF(AND(B19="红利再投",OR(D19<=0,E19<>0,F19<>0)),"再投填正份额、金额0、费用0",IF(AND(OR(B19="现金分红",B19="红利再投"),K18<=0),"分红或再投前须有持仓",IF(AND(OR(OR(B19="买入",B19="定投",B19="转换转入"),B19="卖出"),OR(D19<=0,E19<=0)),"买卖须填正份额、正金额",IF(AND(B19="卖出",D19>K18+0.000001),"卖出份额超过持仓",IF(AND(OR(B19="买入",B19="定投",B19="转换转入"),F19>=E19),"申购费不能达到总支出",IF(NOT(ISNUMBER(持仓总览!$H$6)),"请填写金额核对容差",IF(持仓总览!$H$6<0,"金额核对容差不能为负",IF(NOT(OR(持仓总览!$C$7="利润优先",持仓总览!$C$7="本金优先")),"请选择卖出分配模式",IF(AND(OR(B19="买入",B19="定投",B19="转换转入"),ABS(E19-F19-C19*D19)>持仓总览!$H$6),"买入金额与份额净值不符",IF(AND(B19="卖出",ABS(E19+F19-C19*D19)>持仓总览!$H$6),"到账加费用与赎回市值不符","已计入")))))))))))))))))))))))))) -> 已计入 | J19: =IF(AA19="正常",IF(I19="已计入",IF(OR(OR(B19="买入",B19="定投",B19="转换转入"),B19="红利再投"),D19,IF(B19="卖出",-D19,0)),0),"") -> 94.9 | K19: =IF(AA19="正常",ROUND(K18+J19,6),"") -> 17213.07 | L19: =IF(I19="已计入",ROUND(K18*C19,2),"") -> 36021.77 | M19: =IF(I19="已计入",IF(B19="卖出",MAX(0,L19-Q18-F19),IF(B19="现金分红",MAX(0,L19+E19-Q18),0)),"") -> 0 | N19: =IF(I19="已计入",IF(AND(B19="卖出",持仓总览!$C$7="本金优先"),MAX(0,E19-Q18),IF(OR(B19="卖出",B19="现金分红"),MIN(E19,M19),0)),"") -> 0 | O19: =IF(I19="已计入",IF(OR(B19="卖出",B19="现金分红"),MIN(Q18,MAX(0,E19-N19)),0),"") -> 0 | P19: =IF(I19="已计入",IF(AND(B19="卖出",K19=0),MAX(0,Q18-O19),0),"") -> 0 | Q19: =IF(AA19="正常",IF(I19="已计入",ROUND(Q18+IF(OR(B19="买入",B19="定投",B19="转换转入"),E19,0)-O19-P19,2),Q18),"") -> 34146.01 | R19: =IF(I19="已计入",ROUND(K19*C19,2),"") -> 36221.46 | S19: =IF(I19="已计入",ROUND(R19-Q19,2),"") -> 2075.45 | T19: =IF(I19="已计入",IF(Q19=0,"",S19/Q19),"") -> 0.060781626 | U19: =IF(AA19="正常",U18+IF(AND(I19="已计入",OR(B19="买入",B19="定投",B19="转换转入")),E19,0),"") -> 34146.01 | V19: =IF(AA19="正常",V18+IF(AND(I19="已计入",OR(B19="卖出",B19="现金分红")),E19,0),"") -> 0 | W19: =IF(AA19="正常",W18+IF(I19="已计入",N19,0),"") -> 0 | X19: =IF(AA19="正常",X18+IF(I19="已计入",P19,0),"") -> 0 | Y19: =IF(I19="已计入",ROUND(R19+V19-U19,2),"") -> 2075.45 | Z19: =IF(AA19="正常",IF(I19="已计入",A19,Z18),"") -> 46007 | AA19: =IF(OR(AA18="错误",AND(I19<>"",I19<>"已排除",I19<>"待确认",I19<>"已计入")),"错误","正常") -> 正常 | AB19: =IF(AA19="正常",IF(I19="已计入",C19,AB18),"") -> 2.1043
... A74: 46157 | B74: 定投 | C74: 3.3486 | D74: 29.82 | E74: 100 | F74: 0.15 | G74: 历史估算 | H74: 原下单 2026-05-15T10:53:51 份额、费用及净值日沿用旧表估算 | I74: =IF(COUNTA(A74:H74)=0,"",IF(OR(OR(OR(G74="撤单",G74="交易失败",G74="交易关闭"),G74="交易失败",G74="交易关闭"),G74="交易失败",G74="交易关闭"),"已排除",IF(G74="待确认","待确认",IF(NOT(OR(G74="已确认",G74="历史估算")),"请选择确认状态",IF(NOT(ISNUMBER(A74)),"缺少有效净值日期",IF(OR(A74<=0,A74<>INT(A74)),"净值日期无效",IF(NOT(OR(OR(B74="买入",B74="定投",B74="转换转入"),B74="卖出",B74="现金分红",B74="红利再投")),"请选择交易类型",IF(NOT(ISNUMBER(C74)),"缺少成交净值",IF(C74<=0,"成交净值须大于零",IF(NOT(ISNUMBER(D74)),"缺少确认份额（分红填0）",IF(NOT(ISNUMBER(E74)),"缺少确认金额（再投填0）",IF(NOT(ISNUMBER(F74)),"缺少手续费（无费用填0）",IF(OR(D74<0,E74<0,F74<0),"份额金额费用不能为负",IF(AA73="错误","前行待修正",IF(A74<Z73,"日期需按成交顺序递增",IF(AND(B74="现金分红",OR(D74<>0,E74<=0,F74<>0)),"分红填份额0、费用0、正金额",IF(AND(B74="红利再投",OR(D74<=0,E74<>0,F74<>0)),"再投填正份额、金额0、费用0",IF(AND(OR(B74="现金分红",B74="红利再投"),K73<=0),"分红或再投前须有持仓",IF(AND(OR(OR(B74="买入",B74="定投",B74="转换转入"),B74="卖出"),OR(D74<=0,E74<=0)),"买卖须填正份额、正金额",IF(AND(B74="卖出",D74>K73+0.000001),"卖出份额超过持仓",IF(AND(OR(B74="买入",B74="定投",B74="转换转入"),F74>=E74),"申购费不能达到总支出",IF(NOT(ISNUMBER(持仓总览!$H$6)),"请填写金额核对容差",IF(持仓总览!$H$6<0,"金额核对容差不能为负",IF(NOT(OR(持仓总览!$C$7="利润优先",持仓总览!$C$7="本金优先")),"请选择卖出分配模式",IF(AND(OR(B74="买入",B74="定投",B74="转换转入"),ABS(E74-F74-C74*D74)>持仓总览!$H$6),"买入金额与份额净值不符",IF(AND(B74="卖出",ABS(E74+F74-C74*D74)>持仓总览!$H$6),"到账加费用与赎回市值不符","已计入")))))))))))))))))))))))))) -> 已计入 | J74: =IF(AA74="正常",IF(I74="已计入",IF(OR(OR(B74="买入",B74="定投",B74="转换转入"),B74="红利再投"),D74,IF(B74="卖出",-D74,0)),0),"") -> 29.82 | K74: =IF(AA74="正常",ROUND(K73+J74,6),"") -> 18942.58 | L74: =IF(I74="已计入",ROUND(K73*C74,2),"") -> 63331.27 | M74: =IF(I74="已计入",IF(B74="卖出",MAX(0,L74-Q73-F74),IF(B74="现金分红",MAX(0,L74+E74-Q73),0)),"") -> 0 | N74: =IF(I74="已计入",IF(AND(B74="卖出",持仓总览!$C$7="本金优先"),MAX(0,E74-Q73),IF(OR(B74="卖出",B74="现金分红"),MIN(E74,M74),0)),"") -> 0 | O74: =IF(I74="已计入",IF(OR(B74="卖出",B74="现金分红"),MIN(Q73,MAX(0,E74-N74)),0),"") -> 0 | P74: =IF(I74="已计入",IF(AND(B74="卖出",K74=0),MAX(0,Q73-O74),0),"") -> 0 | Q74: =IF(AA74="正常",IF(I74="已计入",ROUND(Q73+IF(OR(B74="买入",B74="定投",B74="转换转入"),E74,0)-O74-P74,2),Q73),"") -> 38746.01 | R74: =IF(I74="已计入",ROUND(K74*C74,2),"") -> 63431.12 | S74: =IF(I74="已计入",ROUND(R74-Q74,2),"") -> 24685.11 | T74: =IF(I74="已计入",IF(Q74=0,"",S74/Q74),"") -> 0.6371007 | U74: =IF(AA74="正常",U73+IF(AND(I74="已计入",OR(B74="买入",B74="定投",B74="转换转入")),E74,0),"") -> 38746.01 | V74: =IF(AA74="正常",V73+IF(AND(I74="已计入",OR(B74="卖出",B74="现金分红")),E74,0),"") -> 0 | W74: =IF(AA74="正常",W73+IF(I74="已计入",N74,0),"") -> 0 | X74: =IF(AA74="正常",X73+IF(I74="已计入",P74,0),"") -> 0 | Y74: =IF(I74="已计入",ROUND(R74+V74-U74,2),"") -> 24685.11 | Z74: =IF(AA74="正常",IF(I74="已计入",A74,Z73),"") -> 46157 | AA74: =IF(OR(AA73="错误",AND(I74<>"",I74<>"已排除",I74<>"待确认",I74<>"已计入")),"错误","正常") -> 正常 | AB74: =IF(AA74="正常",IF(I74="已计入",C74,AB73),"") -> 3.3486
A75: 46160 | B75: 定投 | C75: 3.289 | D75: 30.36 | E75: 100 | F75: 0.15 | G75: 历史估算 | H75: 原下单 2026-05-18T11:05:01 份额、费用及净值日沿用旧表估算 | I75: =IF(COUNTA(A75:H75)=0,"",IF(OR(OR(OR(G75="撤单",G75="交易失败",G75="交易关闭"),G75="���易失败",G75="交易关闭"),G75="交易失败",G75="交易关闭"),"已排除",IF(G75="待确认","待确认",IF(NOT(OR(G75="已确认",G75="历史估算")),"请选择确认状态",IF(NOT(ISNUMBER(A75)),"缺少有效净值日期",IF(OR(A75<=0,A75<>INT(A75)),"净值日期无效",IF(NOT(OR(OR(B75="买入",B75="定投",B75="转换转入"),B75="卖出",B75="现金分红",B75="红利再投")),"请选择交易类型",IF(NOT(ISNUMBER(C75)),"缺少成交净值",IF(C75<=0,"成交净值须大于零",IF(NOT(ISNUMBER(D75)),"缺少确认份额（分红填0）",IF(NOT(ISNUMBER(E75)),"缺少确认金额（再投填0）",IF(NOT(ISNUMBER(F75)),"缺少手续费（无费用填0）",IF(OR(D75<0,E75<0,F75<0),"份额金额费用不能为负",IF(AA74="错误","前行待修正",IF(A75<Z74,"日期需按成交顺序递增",IF(AND(B75="现金分红",OR(D75<>0,E75<=0,F75<>0)),"分红填份额0、费用0、正金额",IF(AND(B75="红利再投",OR(D75<=0,E75<>0,F75<>0)),"再投填正份额、金额0、费用0",IF(AND(OR(B75="现金分红",B75="红利再投"),K74<=0),"分红或再投前须有持仓",IF(AND(OR(OR(B75="买入",B75="定投",B75="转换转入"),B75="卖出"),OR(D75<=0,E75<=0)),"买卖须填正份额、正金额",IF(AND(B75="卖出",D75>K74+0.000001),"卖出份额超过持仓",IF(AND(OR(B75="买入",B75="定投",B75="转换转入"),F75>=E75),"申购费不能达到总支出",IF(NOT(ISNUMBER(持仓总览!$H$6)),"请填写金额核对容差",IF(持仓总览!$H$6<0,"金额核对容差不能为负",IF(NOT(OR(持仓总览!$C$7="利润优先",持仓总览!$C$7="本金优先")),"请选择卖出分配模式",IF(AND(OR(B75="买入",B75="定投",B75="转换转入"),ABS(E75-F75-C75*D75)>持仓总览!$H$6),"买入金额与份额净值不符",IF(AND(B75="卖出",ABS(E75+F75-C75*D75)>持仓总览!$H$6),"到账加费用与赎回市值不符","已计入")))))))))))))))))))))))))) -> 已计入 | J75: =IF(AA75="正常",IF(I75="已计入",IF(OR(OR(B75="买入",B75="定投",B75="转换转入"),B75="红利再投"),D75,IF(B75="卖出",-D75,0)),0),"") -> 30.36 | K75: =IF(AA75="正常",ROUND(K74+J75,6),"") -> 18972.94 | L75: =IF(I75="已计入",ROUND(K74*C75,2),"") -> 62302.15 | M75: =IF(I75="已计入",IF(B75="卖出",MAX(0,L75-Q74-F75),IF(B75="现金分红",MAX(0,L75+E75-Q74),0)),"") -> 0 | N75: =IF(I75="已计入",IF(AND(B75="卖出",持仓总览!$C$7="本金优先"),MAX(0,E75-Q74),IF(OR(B75="卖出",B75="现金分红"),MIN(E75,M75),0)),"") -> 0 | O75: =IF(I75="已计入",IF(OR(B75="卖出",B75="现金分红"),MIN(Q74,MAX(0,E75-N75)),0),"") -> 0 | P75: =IF(I75="已计入",IF(AND(B75="卖出",K75=0),MAX(0,Q74-O75),0),"") -> 0 | Q75: =IF(AA75="正常",IF(I75="已计入",ROUND(Q74+IF(OR(B75="买入",B75="定投",B75="转换转入"),E75,0)-O75-P75,2),Q74),"") -> 38846.01 | R75: =IF(I75="已计入",ROUND(K75*C75,2),"") -> 62402 | S75: =IF(I75="已计入",ROUND(R75-Q75,2),"") -> 23555.99 | T75: =IF(I75="已计入",IF(Q75=0,"",S75/Q75),"") -> 0.60639407 | U75: =IF(AA75="正常",U74+IF(AND(I75="已计入",OR(B75="买入",B75="定投",B75="转换转入")),E75,0),"") -> 38846.01 | V75: =IF(AA75="正常",V74+IF(AND(I75="已计入",OR(B75="卖出",B75="现金分红")),E75,0),"") -> 0 | W75: =IF(AA75="正常",W74+IF(I75="已计入",N75,0),"") -> 0 | X75: =IF(AA75="正常",X74+IF(I75="已计入",P75,0),"") -> 0 | Y75: =IF(I75="已计入",ROUND(R75+V75-U75,2),"") -> 23555.99 | Z75: =IF(AA75="正常",IF(I75="已计入",A75,Z74),"") -> 46160 | AA75: =IF(OR(AA74="错误",AND(I75<>"",I75<>"已排除",I75<>"待确认",I75<>"已计入")),"错误","正常") -> 正常 | AB75: =IF(AA75="正常",IF(I75="已计入",C75,AB74),"") -> 3.289
A76: 46161 | B76: 定投 | C76: 3.2976 | D76: 30.28 | E76: 100 | F76: 0.15 | G76: 历史估算 | H76: 原下单 2026-05-19T10:53:11 份额、费用及净值日沿用旧表估算 | I76: =IF(COUNTA(A76:H76)=0,"",IF(OR(OR(OR(G76="撤单",G76="交易失败",G76="交易关闭"),G76="交易失败",G76="交易关闭"),G76="交易失败",G76="交易关闭"),"已排除",IF(G76="待确认","待确认",IF(NOT(OR(G76="已确认",G76="历史估算")),"请选择确认状态",IF(NOT(ISNUMBER(A76)),"缺少有效净值日期",IF(OR(A76<=0,A76<>INT(A76)),"净值日期无效",IF(NOT(OR(OR(B76="买入",B76="定投",B76="转换转入"),B76="卖出",B76="现金分红",B76="红利再投")),"请选择交易类型",IF(NOT(ISNUMBER(C76)),"缺少成交净值",IF(C76<=0,"成交净值须大于零",IF(NOT(ISNUMBER(D76)),"缺少确认份额（分红填0）",IF(NOT(ISNUMBER(E76)),"缺少确认金额（再投填0）",IF(NOT(ISNUMBER(F76)),"缺少手续费（无费用填0）",IF(OR(D76<0,E76<0,F76<0),"份额金额费用不能为负",IF(AA75="错误","前行待修正",IF(A76<Z75,"日期需按成交顺序递增",IF(AND(B76="现金分红",OR(D76<>0,E76<=0,F76<>0)),"分红填份额0、费用0、正金额",IF(AND(B76="红利再投",OR(D76<=0,E76<>0,F76<>0)),"再投填正份额、金额0、费用0",IF(AND(OR(B76="现金分红",B76="红利再投"),K75<=0),"分红或再投前须有持仓",IF(AND(OR(OR(B76="买入",B76="定投",B76="转换转入"),B76="卖出"),OR(D76<=0,E76<=0)),"买卖须填正份额、正金额",IF(AND(B76="卖出",D76>K75+0.000001),"卖出份额超过持仓",IF(AND(OR(B76="买入",B76="定投",B76="转换转入"),F76>=E76),"申购费不能达到总支出",IF(NOT(ISNUMBER(持仓总览!$H$6)),"请填写金额核对容差",IF(持仓总览!$H$6<0,"金额核对容差不能为负",IF(NOT(OR(持仓总览!$C$7="利润优先",持仓总览!$C$7="本金优先")),"请选择卖出分配模式",IF(AND(OR(B76="买入",B76="定投",B76="转换转入"),ABS(E76-F76-C76*D76)>持仓总览!$H$6),"买入金额与份额净值不符",IF(AND(B76="卖出",ABS(E76+F76-C76*D76)>持仓总览!$H$6),"到账加费用与赎回市值不符","已计入")))))))))))))))))))))))))) -> 已计入 | J76: =IF(AA76="正常",IF(I76="已计入",IF(OR(OR(B76="买入",B76="定投",B76="转换转入"),B76="红利再投"),D76,IF(B76="卖出",-D76,0)),0),"") -> 30.28 | K76: =IF(AA76="正常",ROUND(K75+J76,6),"") -> 19003.22 | L76: =IF(I76="已计入",ROUND(K75*C76,2),"") -> 62565.17 | M76: =IF(I76="已计入",IF(B76="卖出",MAX(0,L76-Q75-F76),IF(B76="现金分红",MAX(0,L76+E76-Q75),0)),"") -> 0 | N76: =IF(I76="已计入",IF(AND(B76="卖出",持仓总览!$C$7="本金优先"),MAX(0,E76-Q75),IF(OR(B76="卖出",B76="现金分红"),MIN(E76,M76),0)),"") -> 0 | O76: =IF(I76="已计入",IF(OR(B76="卖出",B76="现金分红"),MIN(Q75,MAX(0,E76-N76)),0),"") -> 0 | P76: =IF(I76="已计入",IF(AND(B76="卖出",K76=0),MAX(0,Q75-O76),0),"") -> 0 | Q76: =IF(AA76="正常",IF(I76="已计入",ROUND(Q75+IF(OR(B76="买入",B76="定投",B76="转换转入"),E76,0)-O76-P76,2),Q75),"") -> 38946.01 | R76: =IF(I76="已计入",ROUND(K76*C76,2),"") -> 62665.02 | S76: =IF(I76="已计入",ROUND(R76-Q76,2),"") -> 23719.01 | T76: =IF(I76="已计入",IF(Q76=0,"",S76/Q76),"") -> 0.60902285 | U76: =IF(AA76="正常",U75+IF(AND(I76="已计入",OR(B76="买入",B76="定投",B76="转换转入")),E76,0),"") -> 38946.01 | V76: =IF(AA76="正常",V75+IF(AND(I76="已计入",OR(B76="卖出",B76="现金分红")),E76,0),"") -> 0 | W76: =IF(AA76="正常",W75+IF(I76="已计入",N76,0),"") -> 0 | X76: =IF(AA76="正常",X75+IF(I76="已计入",P76,0),"") -> 0 | Y76: =IF(I76="已计入",ROUND(R76+V76-U76,2),"") -> 23719.01 | Z76: =IF(AA76="正常",IF(I76="已计入",A76,Z75),"") -> 46161 | AA76: =IF(OR(AA75="错误",AND(I76<>"",I76<>"已排除",I76<>"待确认",I76<>"已计入")),"错误","正常") -> 正常 | AB76: =IF(AA76="正常",IF(I76="已计入",C76,AB75),"") -> 3.2976
A77: 46162 | B77: 定投 | C77: 3.3782 | D77: 29.56 | E77: 100 | F77: 0.15 | G77: 历史估算 | H77: 原下单 2026-05-20T10:54:27 份额、费用及净值日沿用旧表估算 | I77: =IF(COUNTA(A77:H77)=0,"",IF(OR(OR(OR(G77="撤单",G77="交易失败",G77="交易关闭"),G77="交易失败",G77="交易关闭"),G77="交易失败",G77="交易关闭"),"已排除",IF(G77="待确认","待确认",IF(NOT(OR(G77="已确认",G77="历史估算")),"请选择确认状态",IF(NOT(ISNUMBER(A77)),"缺少有效净值日期",IF(OR(A77<=0,A77<>INT(A77)),"净值日期无效",IF(NOT(OR(OR(B77="买入",B77="定投",B77="转换转入"),B77="卖出",B77="现金分红",B77="红利再投")),"请选择交易类型",IF(NOT(ISNUMBER(C77)),"缺少成交净值",IF(C77<=0,"成交净值须大于零",IF(NOT(ISNUMBER(D77)),"缺少确认份额（分红填0）",IF(NOT(ISNUMBER(E77)),"缺少确认金额（再投填0）",IF(NOT(ISNUMBER(F77)),"缺少手续费（无费用填0）",IF(OR(D77<0,E77<0,F77<0),"份额金额费用不能为负",IF(AA76="错误","前行待修正",IF(A77<Z76,"日期需按成交顺序递增",IF(AND(B77="现金分红",OR(D77<>0,E77<=0,F77<>0)),"分红填份额0、费用0、正金额",IF(AND(B77="红利再投",OR(D77<=0,E77<>0,F77<>0)),"再投填正份额、金额0、费用0",IF(AND(OR(B77="现金分红",B77="红利再投"),K76<=0),"分红或再投前须有持仓",IF(AND(OR(OR(B77="买入",B77="定投",B77="转换转入"),B77="卖出"),OR(D77<=0,E77<=0)),"买卖须填正份额、正金额",IF(AND(B77="卖出",D77>K76+0.000001),"卖出份额超过持仓",IF(AND(OR(B77="买入",B77="定投",B77="转换转入"),F77>=E77),"申购费不能达到总支出",IF(NOT(ISNUMBER(持仓总览!$H$6)),"请填写金额核对容差",IF(持仓总览!$H$6<0,"金额核对容差不能为负",IF(NOT(OR(持仓总览!$C$7="利润优先",持仓总览!$C$7="本金优先")),"请选择卖出分配模式",IF(AND(OR(B77="买入",B77="定投",B77="转换转入"),ABS(E77-F77-C77*D77)>持仓总览!$H$6),"买入金额与份额净值不符",IF(AND(B77="卖出",ABS(E77+F77-C77*D77)>持仓总览!$H$6),"到账加费用与赎回市值不符","已计入")))))))))))))))))))))))))) -> 已计入 | J77: =IF(AA77="正常",IF(I77="已计入",IF(OR(OR(B77="买入",B77="定投",B77="转换转入"),B77="红利再投"),D77,IF(B77="卖出",-D77,0)),0),"") -> 29.56 | K77: =IF(AA77="正常",ROUND(K76+J77,6),"") -> 19032.78 | L77: =IF(I77="已计入",ROUND(K76*C77,2),"") -> 64196.68 | M77: =IF(I77="已计入",IF(B77="卖出",MAX(0,L77-Q76-F77),IF(B77="现金分红",MAX(0,L77+E77-Q76),0)),"") -> 0 | N77: =IF(I77="已计入",IF(AND(B77="卖出",持仓总览!$C$7="本金优先"),MAX(0,E77-Q76),IF(OR(B77="卖出",B77="现金分红"),MIN(E77,M77),0)),"") -> 0 | O77: =IF(I77="已计入",IF(OR(B77="卖出",B77="现金分红"),MIN(Q76,MAX(0,E77-N77)),0),"") -> 0 | P77: =IF(I77="已计入",IF(AND(B77="卖出",K77=0),MAX(0,Q76-O77),0),"") -> 0 | Q77: =IF(AA77="正常",IF(I77="已计入",ROUND(Q76+IF(OR(B77="买入",B77="定投",B77="转换转入"),E77,0)-O77-P77,2),Q76),"") -> 39046.01 | R77: =IF(I77="已计入",ROUND(K77*C77,2),"") -> 64296.54 | S77: =IF(I77="已计入",ROUND(R77-Q77,2),"") -> 25250.53 | T77: =IF(I77="已计入",IF(Q77=0,"",S77/Q77),"") -> 0.64668656 | U77: =IF(AA77="正常",U76+IF(AND(I77="已计入",OR(B77="买入",B77="定投",B77="转换转入")),E77,0),"") -> 39046.01 | V77: =IF(AA77="正常",V76+IF(AND(I77="已计入",OR(B77="卖出",B77="现金分红")),E77,0),"") -> 0 | W77: =IF(AA77="正常",W76+IF(I77="已计入",N77,0),"") -> 0 | X77: =IF(AA77="正常",X76+IF(I77="已计入",P77,0),"") -> 0 | Y77: =IF(I77="已计入",ROUND(R77+V77-U77,2),"") -> 25250.53 | Z77: =IF(AA77="正常",IF(I77="已计入",A77,Z76),"") -> 46162 | AA77: =IF(OR(AA76="错误",AND(I77<>"",I77<>"已排除",I77<>"待确认",I77<>"已计入")),"错误","正常") -> 正常 | AB77: =IF(AA77="正常",IF(I77="已计入",C77,AB76),"") -> 3.3782
A78: 46163 | B78: 定投 | C78: 3.359 | D78: 2.97 | E78: 10 | F78: 0.02 | G78: 历史估算 | H78: 原下单 2026-05-21T11:41:41 份额、费用及净值日沿用旧表估算 | I78: =IF(COUNTA(A78:H78)=0,"",IF(OR(OR(OR(G78="撤单",G78="交易失败",G78="交易关闭"),G78="交易失败",G78="交易关闭"),G78="交易失败",G78="交易关闭"),"已排除",IF(G78="待确认","待确认",IF(NOT(OR(G78="已确认",G78="历史估算")),"请选择确认状态",IF(NOT(ISNUMBER(A78)),"缺少有效净值日期",IF(OR(A78<=0,A78<>INT(A78)),"净值日期无效",IF(NOT(OR(OR(B78="买入",B78="定投",B78="转换转入"),B78="卖出",B78="现金分红",B78="红利再投")),"请选择交易类型",IF(NOT(ISNUMBER(C78)),"缺少成交净值",IF(C78<=0,"成交净值须大于零",IF(NOT(ISNUMBER(D78)),"缺少确认份额（分红填0）",IF(NOT(ISNUMBER(E78)),"缺少确认金额（再投填0）",IF(NOT(ISNUMBER(F78)),"缺少手续费（无费用填0）",IF(OR(D78<0,E78<0,F78<0),"份额金额费用不能为负",IF(AA77="错误","前行待修正",IF(A78<Z77,"日期需按成交顺序递增",IF(AND(B78="现金分红",OR(D78<>0,E78<=0,F78<>0)),"分红填份额0、费用0、正金额",IF(AND(B78="红利再投",OR(D78<=0,E78<>0,F78<>0)),"再投填正份额、金额0、费用0",IF(AND(OR(B78="现金分红",B78="红利再投"),K77<=0),"分红或再投前须有持仓",IF(AND(OR(OR(B78="买入",B78="定投",B78="转换转入"),B78="卖出"),OR(D78<=0,E78<=0)),"买卖须填正份额、正金额",IF(AND(B78="卖出",D78>K77+0.000001),"卖出份额超过持仓",IF(AND(OR(B78="买入",B78="定投",B78="转换转入"),F78>=E78),"申购费不能达到总支出",IF(NOT(ISNUMBER(持仓总览!$H$6)),"请填写金额核对容差",IF(持仓总览!$H$6<0,"金额核对容差不能为负",IF(NOT(OR(持仓总览!$C$7="利润优先",持仓总览!$C$7="本金优先")),"请选择卖出分配模式",IF(AND(OR(B78="买入",B78="定投",B78="转换转入"),ABS(E78-F78-C78*D78)>持仓总览!$H$6),"买入金额与份额净值不符",IF(AND(B78="卖出",ABS(E78+F78-C78*D78)>持仓总览!$H$6),"到账加费用与赎回市值不符","已计入")))))))))))))))))))))))))) -> 已计入 | J78: =IF(AA78="正常",IF(I78="已计入",IF(OR(OR(B78="买入",B78="定投",B78="转换转入"),B78="红利再投"),D78,IF(B78="卖出",-D78,0)),0),"") -> 2.97 | K78: =IF(AA78="正常",ROUND(K77+J78,6),"") -> 19035.75 | L78: =IF(I78="已计入",ROUND(K77*C78,2),"") -> 63931.11 | M78: =IF(I78="已计入",IF(B78="卖出",MAX(0,L78-Q77-F78),IF(B78="现金分红",MAX(0,L78+E78-Q77),0)),"") -> 0 | N78: =IF(I78="已计入",IF(AND(B78="卖出",持仓总览!$C$7="本金优先"),MAX(0,E78-Q77),IF(OR(B78="卖出",B78="现金分红"),MIN(E78,M78),0)),"") -> 0 | O78: =IF(I78="已计入",IF(OR(B78="卖出",B78="现金分红"),MIN(Q77,MAX(0,E78-N78)),0),"") -> 0 | P78: =IF(I78="已计入",IF(AND(B78="卖出",K78=0),MAX(0,Q77-O78),0),"") -> 0 | Q78: =IF(AA78="正常",IF(I78="已计入",ROUND(Q77+IF(OR(B78="买入",B78="定投",B78="转换转入"),E78,0)-O78-P78,2),Q77),"") -> 39056.01 | R78: =IF(I78="已计入",ROUND(K78*C78,2),"") -> 63941.08 | S78: =IF(I78="已计入",ROUND(R78-Q78,2),"") -> 24885.07 | T78: =IF(I78="已计入",IF(Q78=0,"",S78/Q78),"") -> 0.63716365 | U78: =IF(AA78="正常",U77+IF(AND(I78="已计入",OR(B78="买入",B78="定投",B78="转换转入")),E78,0),"") -> 39056.01 | V78: =IF(AA78="正常",V77+IF(AND(I78="已计入",OR(B78="卖出",B78="现金分红")),E78,0),"") -> 0 | W78: =IF(AA78="正常",W77+IF(I78="已计入",N78,0),"") -> 0 | X78: =IF(AA78="正常",X77+IF(I78="已计入",P78,0),"") -> 0 | Y78: =IF(I78="已计入",ROUND(R78+V78-U78,2),"") -> 24885.07 | Z78: =IF(AA78="正常",IF(I78="已计入",A78,Z77),"") -> 46163 | AA78: =IF(OR(AA77="错误",AND(I78<>"",I78<>"已排除",I78<>"待确认",I78<>"已计入")),"错误","正常") -> 正常 | AB78: =IF(AA78="正常",IF(I78="已计入",C78,AB77),"") -> 3.359
A79: 46164 | B79: 定投 | C79: 3.4943 | D79: 14.29 | E79: 50 | F79: 0.08 | G79: 历史估算 | H79: 原下单 2026-05-22T11:38:01 份额、费用及净值日沿用旧表估算 | I79: =IF(COUNTA(A79:H79)=0,"",IF(OR(OR(OR(G79="撤单",G79="交易失败",G79="交易关闭"),G79="交易失败",G79="交易关闭"),G79="交易失败",G79="交易关闭"),"已排除",IF(G79="待确认","待确认",IF(NOT(OR(G79="已确认",G79="历史估算")),"请选择确认状态",IF(NOT(ISNUMBER(A79)),"缺少有效净值日期",IF(OR(A79<=0,A79<>INT(A79)),"净值日期无效",IF(NOT(OR(OR(B79="买入",B79="定投",B79="转换转入"),B79="卖出",B79="现金分红",B79="红利再投")),"请选择交易类型",IF(NOT(ISNUMBER(C79)),"缺少成交净值",IF(C79<=0,"成交净值须大于零",IF(NOT(ISNUMBER(D79)),"缺少确认份额（分红填0）",IF(NOT(ISNUMBER(E79)),"缺少确认金额（再投填0）",IF(NOT(ISNUMBER(F79)),"缺少手续费（无费用填0）",IF(OR(D79<0,E79<0,F79<0),"份额金额费用不能为负",IF(AA78="错误","前行待修正",IF(A79<Z78,"日期需按成交顺序递增",IF(AND(B79="现金分红",OR(D79<>0,E79<=0,F79<>0)),"分红填份额0、费用0、正金额",IF(AND(B79="红利再投",OR(D79<=0,E79<>0,F79<>0)),"再投填正份额、金额0、费用0",IF(AND(OR(B79="现金分红",B79="红利再投"),K78<=0),"分红或再投前须有持仓",IF(AND(OR(OR(B79="买入",B79="定投",B79="转换转入"),B79="卖出"),OR(D79<=0,E79<=0)),"买卖须填正份额、正金额",IF(AND(B79="卖出",D79>K78+0.000001),"卖出份额超过持仓",IF(AND(OR(B79="买入",B79="定投",B79="转换转入"),F79>=E79),"申购费不能达到总支出",IF(NOT(ISNUMBER(持仓总览!$H$6)),"请填写金额核对容差",IF(持仓总览!$H$6<0,"金额核对容差不能为负",IF(NOT(OR(持仓总览!$C$7="利润优先",持仓总览!$C$7="本金优先")),"请选择卖出分配模式",IF(AND(OR(B79="买入",B79="定投",B79="转换转入"),ABS(E79-F79-C79*D79)>持仓总览!$H$6),"买入金额与份额净值不符",IF(AND(B79="卖出",ABS(E79+F79-C79*D79)>持仓总览!$H$6),"到账加费用与赎回市值不符","已计入")))))))))))))))))))))))))) -> 已计入 | J79: =IF(AA79="正常",IF(I79="已计入",IF(OR(OR(B79="买入",B79="定投",B79="转换转入"),B79="红利再投"),D79,IF(B79="卖出",-D79,0)),0),"") -> 14.29 | K79: =IF(AA79="正常",ROUND(K78+J79,6),"") -> 19050.04 | L79: =IF(I79="已计入",ROUND(K78*C79,2),"") -> 66516.62 | M79: =IF(I79="已计入",IF(B79="卖出",MAX(0,L79-Q78-F79),IF(B79="现金分红",MAX(0,L79+E79-Q78),0)),"") -> 0 | N79: =IF(I79="已计入",IF(AND(B79="卖出",持仓总览!$C$7="本金优先"),MAX(0,E79-Q78),IF(OR(B79="卖出",B79="现金分红"),MIN(E79,M79),0)),"") -> 0 | O79: =IF(I79="已计入",IF(OR(B79="卖出",B79="现金分红"),MIN(Q78,MAX(0,E79-N79)),0),"") -> 0 | P79: =IF(I79="已计入",IF(AND(B79="卖出",K79=0),MAX(0,Q78-O79),0),"") -> 0 | Q79: =IF(AA79="正常",IF(I79="已计入",ROUND(Q78+IF(OR(B79="买入",B79="定投",B79="转换转入"),E79,0)-O79-P79,2),Q78),"") -> 39106.01 | R79: =IF(I79="已计入",ROUND(K79*C79,2),"") -> 66566.55 | S79: =IF(I79="已计入",ROUND(R79-Q79,2),"") -> 27460.54 | T79: =IF(I79="已计入",IF(Q79=0,"",S79/Q79),"") -> 0.70220767 | U79: =IF(AA79="正常",U78+IF(AND(I79="已计入",OR(B79="买入",B79="定投",B79="转换转入")),E79,0),"") -> 39106.01 | V79: =IF(AA79="正常",V78+IF(AND(I79="已计入",OR(B79="卖出",B79="现金分红")),E79,0),"") -> 0 | W79: =IF(AA79="正常",W78+IF(I79="已计入",N79,0),"") -> 0 | X79: =IF(AA79="正常",X78+IF(I79="已计入",P79,0),"") -> 0 | Y79: =IF(I79="已计入",ROUND(R79+V79-U79,2),"") -> 27460.54 | Z79: =IF(AA79="正常",IF(I79="已计入",A79,Z78),"") -> 46164 | AA79: =IF(OR(AA78="错误",AND(I79<>"",I79<>"已排除",I79<>"待确认",I79<>"已计入")),"错误","正常") -> 正常 | AB79: =IF(AA79="正常",IF(I79="已计入",C79,AB78),"") -> 3.4943
